Workbook

Sheet COVER
C3: =UPPER(NAMA_USAHA) -> KOPI PARANG
C5: LAPORAN KEUANGAN
C6: ="Periode 1 Januari – "&TEXT(DATE(TAHUN,BLN+1,0),"d")&" "&NAMA_BLN&" "&TAHUN -> Periode 1 Januari – 30 September 2026
C10: DAFTAR ISI
B11: 1 | C11: PENGATURAN | D11: Tahun, bulan tutup buku, tarif pajak, target
B12: 2 | C12: DASHBOARD | D12: Ringkasan kinerja, grafik, cek kesehatan data
B13: 3 | C13: LABA RUGI | D13: Laporan laba rugi bulanan (multi-step)
B14: 4 | C14: NERACA | D14: Laporan posisi keuangan
B15: 5 | C15: ARUS KAS | D15: Arus kas metode langsung
B16: 6 | C16: PERUBAHAN EKUITAS | D16: Mutasi modal pemilik
B17: 7 | C17: CALK | D17: Catatan atas laporan keuangan
B18: 8 | C18: REVIEW | D18: Temuan review & tindak lanjut
B19: 9 | C19: PAJAK | D19: Rekonsiliasi pajak restoran (PBJT)
B20: 10 | C20: ANALISIS EVENT | D20: Laba rugi per event
B21: 11 | C21: REKAP OMZET | D21: Rekap omzet bulanan & KPI penjualan
B22: 12 | C22: OMZET HARIAN | D22: INPUT — omzet & realisasi harian
... B28: 18 | C28: MUTASI | D28: Sheet hitung (jangan diubah)
C30: CARA PAKAI
C31: 1. Setiap hari: isi OMZET HARIAN (angka POS, lalu realisasi setoran H+1).
C32: 2. Setiap transaksi: isi satu baris di JURNAL (tanggal, akun debet, akun kredit, nominal, keterangan, tag event bila ada).
C33: 3. Akhir bulan: stok opname, cek kas opname, isi gaji & sewa, lalu ubah "bulan tutup buku" di PENGATURAN.
C34: 4. Buka DASHBOARD → pastikan semua cek kesehatan data ✔ sebelum laporan dibagikan.
C36: KODE WARNA
C37: Teks biru | D37: Data input manual
C38: Latar kuning | D38: Pengaturan / input penting
C39: Teks hitam | D39: Rumus — jangan ditimpa
C40: Latar abu-abu | D40: Kolom bantu rumus
C41: Baris coklat muda miring | D41: Jurnal otomatis / penyesuaian
C44: Disusun mengacu SAK EMKM. Dibuat ulang dari file KOPI_PARANG_FINANCIAL_REPORT_1.xlsx.

Sheet PENGATURAN
A1: PENGATURAN
A2: Sel kuning = boleh diubah. Semua laporan otomatis menyesuaikan.
B3: Parameter | C3: Nilai | D3: Keterangan
B4: Nama usaha | C4: Kopi Parang | D4: Nama yang tampil di semua laporan | F4: No | G4: Bulan
B5: Tahun buku | C5: 2026 | D5: Tahun laporan | F5: 1 | G5: Januari
B6: Bulan tutup buku terakhir (1–12) | C6: 9 | D6: Laporan dihitung s.d. bulan ini. Oktober belum lengkap (gaji, sewa, pajak belum dicatat), jadi diset ke 9 = September. | F6: 2 | G6: Februari
B7: Nama bulan tutup buku | C7: =INDEX($G$5:$G$16,$C$6) -> September | D7: Otomatis | F7: 3 | G7: Maret
B8: Tarif PBJT makanan & minuman | C8: 0.1 | D8: Pajak Barang & Jasa Tertentu (pajak restoran) daerah | F8: 4 | G8: April
B9: Harga menu sudah termasuk PBJT? (YA/TIDAK) | C9: YA | D9: YA = pajak dihitung 10/110 dari omzet; TIDAK = 10% dari omzet. Pastikan sesuai praktik di kasir. | F9: 5 | G9: Mei
B10: Akui estimasi PBJT kurang bayar di laporan? (YA/TIDAK) | C10: YA | D10: Disarankan YA: laporan yang ditunjukkan ke pihak luar harus memuat kewajiban ini. Lihat sheet PAJAK & REVIEW. | F10: 6 | G10: Juni
F11: 7 | G11: Juli
B12: Target omzet bulanan (Rp) | C12: 100000000 | D12: CONTOH — ganti dengan target kamu sendiri | F12: 8 | G12: Agustus
F13: 9 | G13: September
B14: Batas food cost (HPP / pendapatan) | C14: 0.35 | D14: Patokan umum F&B 28–35%; sesuaikan | F14: 10 | G14: Oktober
B15: Batas biaya gaji (payroll / pendapatan) | C15: 0.3 | D15: Patokan umum F&B 25–30%; sesuaikan | F15: 11 | G15: November
B16: Batas sewa (occupancy / pendapatan) | C16: 0.1 | D16: Patokan umum F&B 6–10%; sesuaikan | F16: 12 | G16: Desember
B17: Batas prime cost (HPP + gaji) | C17: 0.65 | D17: Patokan umum F&B 60–65%; sesuaikan
B18: Target net margin minimal | C18: 0.1 | D18: Patokan umum cafe sehat 10–15%; sesuaikan

Sheet DASHBOARD
B1: =UPPER(NAMA_USAHA)&" — RINGKASAN KEUANGAN" -> KOPI PARANG — RINGKASAN KEUANGAN
B2: ="Periode 1 Januari – "&TEXT(DATE(TAHUN,BLN+1,0),"d")&" "&NAMA_BLN&" "&TAHUN -> Periode 1 Januari – 30 September 2026
B4: Pendapatan Bersih | E4: Laba Kotor | H4: Laba (Rugi) Bersih | K4: Total Kas
B5: ='LABA RUGI'!$O$11 -> 795505902 | E5: ='LABA RUGI'!$O$18 -> 456926368 | H5: ='LABA RUGI'!$O$43 -> -54996702 | K5: =NERACA!D7+NERACA!D8+NERACA!D9 -> 53281608
B6: ="Rata-rata "&TEXT('LABA RUGI'!$O$11/BLN,"#,##0")&" / bulan" -> Rata-rata 88,389,545 / bulan | E6: ="Margin "&TEXT('LABA RUGI'!$O$19,"0.0%") -> Margin 57.4% | H6: ="Margin "&TEXT('LABA RUGI'!$O$44,"0.0%") -> Margin -6.9% | K6: ="Tunai "&TEXT(NERACA!D7,"#,##0") -> Tunai 51,913,400
B8: Omzet Bersih / Hari | E8: Rata-rata / Transaksi | H8: Food Cost | K8: Prime Cost
B9: =IFERROR(SUMPRODUCT(('REKAP OMZET'!$C$5:$N$5<=BLN)*'REKAP OMZET'!$C$16:$N$16)/SUMPRODUCT(('REKAP OMZET'!$C$5:$N$5<=BLN)*'REKAP OMZET'!$C$18:$N$18),0) -> 3179316.8 | E9: =IFERROR(SUMPRODUCT(('REKAP OMZET'!$C$5:$N$5<=BLN)*'REKAP OMZET'!$C$16:$N$16)/SUMPRODUCT(('REKAP OMZET'!$C$5:$N$5<=BLN)*'REKAP OMZET'!$C$20:$N$20),0) -> 48707.191 | H9: ='LABA RUGI'!$O$47 -> 0.42561536 | K9: ='LABA RUGI'!$O$50 -> 0.74480114
B10: ="rata-rata hari buka" -> rata-rata hari buka | E10: ="avg ticket" -> avg ticket | H10: ="batas "&TEXT(MX_FOOD,"0%") -> batas 35% | K10: ="HPP + gaji, batas "&TEXT(MX_PRIME,"0%") -> HPP + gaji, batas 65%
B12: KINERJA BULANAN
B13: Bulan | C13: Pendapatan Bersih | E13: Laba Kotor | F13: Laba Bersih | H13: Food Cost | I13: Payroll | K13: Kas Akhir
B14: Jan | C14: =IF(1>BLN,0,N('LABA RUGI'!C11)) -> 90280982 | E14: =IF(1>BLN,0,N('LABA RUGI'!C18)) -> 62112682 | F14: =IF(1>BLN,0,N('LABA RUGI'!C43)) -> -51148041 | H14: =IF(1>BLN,"",'LABA RUGI'!C47) -> 0.31200702 | I14: =IF(1>BLN,"",'LABA RUGI'!C48) -> 0.28389146 | K14: =IF(1>BLN,"",'ARUS KAS'!C28) -> 50335039
B15: Feb | C15: =IF(2>BLN,0,N('LABA RUGI'!D11)) -> 68311343 | E15: =IF(2>BLN,0,N('LABA RUGI'!D18)) -> 37077633 | F15: =IF(2>BLN,0,N('LABA RUGI'!D43)) -> -6212118 | H15: =IF(2>BLN,"",'LABA RUGI'!D47) -> 0.45722582 | I15: =IF(2>BLN,"",'LABA RUGI'!D48) -> 0.39077698 | K15: =IF(2>BLN,"",'ARUS KAS'!D28) -> 45123333
B16: Mar | C16: =IF(3>BLN,0,N('LABA RUGI'!E11)) -> 93204021 | E16: =IF(3>BLN,0,N('LABA RUGI'!E18)) -> 60166834 | F16: =IF(3>BLN,0,N('LABA RUGI'!E43)) -> -3403297 | H16: =IF(3>BLN,"",'LABA RUGI'!E47) -> 0.35446096 | I16: =IF(3>BLN,"",'LABA RUGI'!E48) -> 0.46030203 | K16: =IF(3>BLN,"",'ARUS KAS'!E28) -> 43724486
B17: Apr | C17: =IF(4>BLN,0,N('LABA RUGI'!F11)) -> 85954724 | E17: =IF(4>BLN,0,N('LABA RUGI'!F18)) -> 29785930 | F17: =IF(4>BLN,0,N('LABA RUGI'!F43)) -> -20407510 | H17: =IF(4>BLN,"",'LABA RUGI'!F47) -> 0.65346954 | I17: =IF(4>BLN,"",'LABA RUGI'!F48) -> 0.31721351 | K17: =IF(4>BLN,"",'ARUS KAS'!F28) -> 27358556
B18: Mei | C18: =IF(5>BLN,0,N('LABA RUGI'!G11)) -> 102494869 | E18: =IF(5>BLN,0,N('LABA RUGI'!G18)) -> 67769696 | F18: =IF(5>BLN,0,N('LABA RUGI'!G43)) -> 16080376 | H18: =IF(5>BLN,"",'LABA RUGI'!G47) -> 0.33879914 | I18: =IF(5>BLN,"",'LABA RUGI'!G48) -> 0.28689566 | K18: =IF(5>BLN,"",'ARUS KAS'!G28) -> 45262022
B19: Jun | C19: =IF(6>BLN,0,N('LABA RUGI'!H11)) -> 95817091 | E19: =IF(6>BLN,0,N('LABA RUGI'!H18)) -> 50680584 | F19: =IF(6>BLN,0,N('LABA RUGI'!H43)) -> 5382034 | H19: =IF(6>BLN,"",'LABA RUGI'!H47) -> 0.47106948 | I19: =IF(6>BLN,"",'LABA RUGI'!H48) -> 0.31615793 | K19: =IF(6>BLN,"",'ARUS KAS'!H28) -> 50562532
B20: Jul | C20: =IF(7>BLN,0,N('LABA RUGI'!I11)) -> 85381495 | E20: =IF(7>BLN,0,N('LABA RUGI'!I18)) -> 51463451 | F20: =IF(7>BLN,0,N('LABA RUGI'!I43)) -> 4796009 | H20: =IF(7>BLN,"",'LABA RUGI'!I47) -> 0.39725287 | I20: =IF(7>BLN,"",'LABA RUGI'!I48) -> 0.26658391 | K20: =IF(7>BLN,"",'ARUS KAS'!I28) -> 48081893
B21: Agu | C21: =IF(8>BLN,0,N('LABA RUGI'!J11)) -> 87841757 | E21: =IF(8>BLN,0,N('LABA RUGI'!J18)) -> 64748737 | F21: =IF(8>BLN,0,N('LABA RUGI'!J43)) -> 17725947 | H21: =IF(8>BLN,"",'LABA RUGI'!J47) -> 0.26289342 | I21: =IF(8>BLN,"",'LABA RUGI'!J48) -> 0.27514628 | K21: =IF(8>BLN,"",'ARUS KAS'!J28) -> 68054513
B22: Sep | C22: =IF(9>BLN,0,N('LABA RUGI'!K11)) -> 86219620 | E22: =IF(9>BLN,0,N('LABA RUGI'!K18)) -> 33120821 | F22: =IF(9>BLN,0,N('LABA RUGI'!K43)) -> -17810102 | H22: =IF(9>BLN,"",'LABA RUGI'!K47) -> 0.61585517 | I22: =IF(9>BLN,"",'LABA RUGI'!K48) -> 0.28754862 | K22: =IF(9>BLN,"",'ARUS KAS'!K28) -> 53281608
B23: Okt | C23: =IF(10>BLN,0,N('LABA RUGI'!L11)) -> 0 | E23: =IF(10>BLN,0,N('LABA RUGI'!L18)) -> 0 | F23: =IF(10>BLN,0,N('LABA RUGI'!L43)) -> 0 | H23: =IF(10>BLN,"",'LABA RUGI'!L47) | I23: =IF(10>BLN,"",'LABA RUGI'!L48) | K23: =IF(10>BLN,"",'ARUS KAS'!L28)
B24: Nov | C24: =IF(11>BLN,0,N('LABA RUGI'!M11)) -> 0 | E24: =IF(11>BLN,0,N('LABA RUGI'!M18)) -> 0 | F24: =IF(11>BLN,0,N('LABA RUGI'!M43)) -> 0 | H24: =IF(11>BLN,"",'LABA RUGI'!M47) | I24: =IF(11>BLN,"",'LABA RUGI'!M48) | K24: =IF(11>BLN,"",'ARUS KAS'!M28)
B25: Des | C25: =IF(12>BLN,0,N('LABA RUGI'!N11)) -> 0 | E25: =IF(12>BLN,0,N('LABA RUGI'!N18)) -> 0 | F25: =IF(12>BLN,0,N('LABA RUGI'!N43)) -> 0 | H25: =IF(12>BLN,"",'LABA RUGI'!N47) | I25: =IF(12>BLN,"",'LABA RUGI'!N48) | K25: =IF(12>BLN,"",'ARUS KAS'!N28)
B45: STRUKTUR BIAYA (s.d. tutup buku)
B46: Pos | C46: Rupiah | E46: % Pendapatan
B47: HPP | C47: ='LABA RUGI'!$O$16 -> 338579534 | E47: =IFERROR(C47/'LABA RUGI'!$O$11,"") -> 0.42561536
B48: Gaji | C48: ='LABA RUGI'!$O$22 -> 253914165 | E48: =IFERROR(C48/'LABA RUGI'!$O$11,"") -> 0.31918577
B49: Sewa | C49: ='LABA RUGI'!$O$23 -> 80000000 | E49: =IFERROR(C49/'LABA RUGI'!$O$11,"") -> 0.10056494
B50: Marketing & event | C50: ='LABA RUGI'!$O$25 -> 79193298 | E50: =IFERROR(C50/'LABA RUGI'!$O$11,"") -> 0.099550862
B51: Tagihan bulanan | C51: ='LABA RUGI'!$O$24 -> 45436921 | E51: =IFERROR(C51/'LABA RUGI'!$O$11,"") -> 0.057117013
B52: Beban lainnya | C52: ='LABA RUGI'!$O$33-'LABA RUGI'!$O$22-'LABA RUGI'!$O$23-'LABA RUGI'!$O$25-'LABA RUGI'!$O$24 -> 50765307 | E52: =IFERROR(C52/'LABA RUGI'!$O$11,"") -> 0.063815123
B53: Sisa (laba/rugi) | C53: ='LABA RUGI'!$O$11-SUM(C47:C52) -> -52383323 | E53: =IFERROR(C53/'LABA RUGI'!$O$11,"") -> -0.065849069
B56: CEK KESEHATAN DATA
B57: Neraca seimbang | F57: =IF(NERACA!D38=0,"✔ OK","✘ Selisih "&TEXT(NERACA!D38,"#,##0")) -> ✔ OK
B58: Neraca saldo seimbang | F58: =IF('NERACA SALDO'!G41=0,"✔ OK","✘ Tidak seimbang") -> ✔ OK
B59: Kas di arus kas = kas di neraca | F59: =IF('ARUS KAS'!O29=0,"✔ OK","✘ Selisih") -> ✔ OK
B60: Ekuitas: laporan perubahan = neraca | F60: =IF('PERUBAHAN EKUITAS'!O12=0,"✔ OK","✘ Selisih") -> ✔ OK
B61: Daftar aset tetap = akun Peralatan | F61: =IF('ASET TETAP'!D27=0,"✔ OK","✘ Selisih") -> ✔ OK
B62: Jurnal dengan akun tidak dikenal | F62: =IF(COUNTIF(J_CEK,"⚠*")=0,"✔ Tidak ada",COUNTIF(J_CEK,"⚠*")&" baris — cek kolom R JURNAL") -> ✔ Tidak ada
B63: Hari omzet belum direalisasi / perlu cek | F63: =IF('REKAP OMZET'!O26=0,"✔ Tidak ada",'REKAP OMZET'!O26&" hari — cek OMZET HARIAN") -> 12 hari — cek OMZET HARIAN
B64: Saldo awal aset tetap (pra-2026) | F64: =IF('ASET TETAP'!D24=0,"⚠ Belum diinventarisasi","✔ Terisi") -> ⚠ Belum diinventarisasi
...

Sheet LABA RUGI
A1: LAPORAN LABA RUGI
A2: ="KOPI PARANG • "&"Periode 1 Januari – "&TEXT(DATE(TAHUN,BLN+1,0),"d")&" "&NAMA_BLN&" "&TAHUN&" • dalam Rupiah" -> KOPI PARANG • Periode 1 Januari – 30 September 2026 • dalam Rupiah
B4: Keterangan | C4: Jan | D4: Feb | E4: Mar | F4: Apr | G4: Mei | H4: Jun | I4: Jul | J4: Agu | K4: Sep | L4: Okt | M4: Nov | N4: Des | O4: ="s.d. "&LEFT(NAMA_BLN,3)&" "&TAHUN -> s.d. Sep 2026 | P4: % Pend.
C5: 1 | D5: 2 | E5: 3 | F5: 4 | G5: 5 | H5: 6 | I5: 7 | J5: 8 | K5: 9 | L5: 10 | M5: 11 | N5: 12
B6: PENDAPATAN USAHA
B7: Penjualan cafe | C7: =IF(C$5>BLN,"",-SUMIF(MUTASI!$B$6:$B$45,"Pendapatan Cafe",MUTASI!$E$6:$E$45)) -> 90683177 | D7: =IF(D$5>BLN,"",-SUMIF(MUTASI!$B$6:$B$45,"Pendapatan Cafe",MUTASI!$F$6:$F$45)) -> 73106388 | E7: =IF(E$5>BLN,"",-SUMIF(MUTASI!$B$6:$B$45,"Pendapatan Cafe",MUTASI!$G$6:$G$45)) -> 102509844 | F7: =IF(F$5>BLN,"",-SUMIF(MUTASI!$B$6:$B$45,"Pendapatan Cafe",MUTASI!$H$6:$H$45)) -> 94551888 | G7: =IF(G$5>BLN,"",-SUMIF(MUTASI!$B$6:$B$45,"Pendapatan Cafe",MUTASI!$I$6:$I$45)) -> 111312774 | H7: =IF(H$5>BLN,"",-SUMIF(MUTASI!$B$6:$B$45,"Pendapatan Cafe",MUTASI!$J$6:$J$45)) -> 105398227 | I7: =IF(I$5>BLN,"",-SUMIF(MUTASI!$B$6:$B$45,"Pendapatan Cafe",MUTASI!$K$6:$K$45)) -> 93923281 | J7: =IF(J$5>BLN,"",-SUMIF(MUTASI!$B$6:$B$45,"Pendapatan Cafe",MUTASI!$L$6:$L$45)) -> 94790934 | K7: =IF(K$5>BLN,"",-SUMIF(MUTASI!$B$6:$B$45,"Pendapatan Cafe",MUTASI!$M$6:$M$45)) -> 92214820 | L7: =IF(L$5>BLN,"",-SUMIF(MUTASI!$B$6:$B$45,"Pendapatan Cafe",MUTASI!$N$6:$N$45)) | M7: =IF(M$5>BLN,"",-SUMIF(MUTASI!$B$6:$B$45,"Pendapatan Cafe",MUTASI!$O$6:$O$45)) | N7: =IF(N$5>BLN,"",-SUMIF(MUTASI!$B$6:$B$45,"Pendapatan Cafe",MUTASI!$P$6:$P$45)) | O7: =-SUMIF(MUTASI!$B$6:$B$45,"Pendapatan Cafe",MUTASI!$R$6:$R$45) -> 858491333 | P7: =IFERROR(O7/O11,"") -> 1.0791766
B8: Pendapatan event & non-cafe | C8: =IF(C$5>BLN,"",-SUMIF(MUTASI!$B$6:$B$45,"Pendapatan non Cafe",MUTASI!$E$6:$E$45)) -> 7870000 | D8: =IF(D$5>BLN,"",-SUMIF(MUTASI!$B$6:$B$45,"Pendapatan non Cafe",MUTASI!$F$6:$F$45)) -> 1860000 | E8: =IF(E$5>BLN,"",-SUMIF(MUTASI!$B$6:$B$45,"Pendapatan non Cafe",MUTASI!$G$6:$G$45)) -> 0 | F8: =IF(F$5>BLN,"",-SUMIF(MUTASI!$B$6:$B$45,"Pendapatan non Cafe",MUTASI!$H$6:$H$45)) -> 0 | G8: =IF(G$5>BLN,"",-SUMIF(MUTASI!$B$6:$B$45,"Pendapatan non Cafe",MUTASI!$I$6:$I$45)) -> 1300000 | H8: =IF(H$5>BLN,"",-SUMIF(MUTASI!$B$6:$B$45,"Pendapatan non Cafe",MUTASI!$J$6:$J$45)) -> 0 | I8: =IF(I$5>BLN,"",-SUMIF(MUTASI!$B$6:$B$45,"Pendapatan non Cafe",MUTASI!$K$6:$K$45)) -> 0 | J8: =IF(J$5>BLN,"",-SUMIF(MUTASI!$B$6:$B$45,"Pendapatan non Cafe",MUTASI!$L$6:$L$45)) -> 1678800 | K8: =IF(K$5>BLN,"",-SUMIF(MUTASI!$B$6:$B$45,"Pendapatan non Cafe",MUTASI!$M$6:$M$45)) -> 2394250 | L8: =IF(L$5>BLN,"",-SUMIF(MUTASI!$B$6:$B$45,"Pendapatan non Cafe",MUTASI!$N$6:$N$45)) | M8: =IF(M$5>BLN,"",-SUMIF(MUTASI!$B$6:$B$45,"Pendapatan non Cafe",MUTASI!$O$6:$O$45)) | N8: =IF(N$5>BLN,"",-SUMIF(MUTASI!$B$6:$B$45,"Pendapatan non Cafe",MUTASI!$P$6:$P$45)) | O8: =-SUMIF(MUTASI!$B$6:$B$45,"Pendapatan non Cafe",MUTASI!$R$6:$R$45) -> 15103050 | P8: =IFERROR(O8/O11,"") -> 0.018985466
B9: Pendapatan kotor | C9: =IF(C$5>BLN,"",N(C7)+N(C8)) -> 98553177 | D9: =IF(D$5>BLN,"",N(D7)+N(D8)) -> 74966388 | E9: =IF(E$5>BLN,"",N(E7)+N(E8)) -> 102509844 | F9: =IF(F$5>BLN,"",N(F7)+N(F8)) -> 94551888 | G9: =IF(G$5>BLN,"",N(G7)+N(G8)) -> 112612774 | H9: =IF(H$5>BLN,"",N(H7)+N(H8)) -> 105398227 | I9: =IF(I$5>BLN,"",N(I7)+N(I8)) -> 93923281 | J9: =IF(J$5>BLN,"",N(J7)+N(J8)) -> 96469734 | ... N9: =IF(N$5>BLN,"",N(N7)+N(N8)) | O9: =N(O7)+N(O8) -> 873594383 | P9: =IFERROR(O9/O11,"") -> 1.098162
B10: Dikurangi: pajak restoran (PBJT) | C10: =IF(C$5>BLN,"",SUMIF(MUTASI!$B$6:$B$45,"Pajak Restoran",MUTASI!$E$6:$E$45)) -> 8272195 | D10: =IF(D$5>BLN,"",SUMIF(MUTASI!$B$6:$B$45,"Pajak Restoran",MUTASI!$F$6:$F$45)) -> 6655045 | E10: =IF(E$5>BLN,"",SUMIF(MUTASI!$B$6:$B$45,"Pajak Restoran",MUTASI!$G$6:$G$45)) -> 9305823 | F10: =IF(F$5>BLN,"",SUMIF(MUTASI!$B$6:$B$45,"Pajak Restoran",MUTASI!$H$6:$H$45)) -> 8597164 | G10: =IF(G$5>BLN,"",SUMIF(MUTASI!$B$6:$B$45,"Pajak Restoran",MUTASI!$I$6:$I$45)) -> 10117905 | H10: =IF(H$5>BLN,"",SUMIF(MUTASI!$B$6:$B$45,"Pajak Restoran",MUTASI!$J$6:$J$45)) -> 9581136 | I10: =IF(I$5>BLN,"",SUMIF(MUTASI!$B$6:$B$45,"Pajak Restoran",MUTASI!$K$6:$K$45)) -> 8541786 | J10: =IF(J$5>BLN,"",SUMIF(MUTASI!$B$6:$B$45,"Pajak Restoran",MUTASI!$L$6:$L$45)) -> 8627977 | K10: =IF(K$5>BLN,"",SUMIF(MUTASI!$B$6:$B$45,"Pajak Restoran",MUTASI!$M$6:$M$45)) -> 8389450 | L10: =IF(L$5>BLN,"",SUMIF(MUTASI!$B$6:$B$45,"Pajak Restoran",MUTASI!$N$6:$N$45)) | M10: =IF(M$5>BLN,"",SUMIF(MUTASI!$B$6:$B$45,"Pajak Restoran",MUTASI!$O$6:$O$45)) | N10: =IF(N$5>BLN,"",SUMIF(MUTASI!$B$6:$B$45,"Pajak Restoran",MUTASI!$P$6:$P$45)) | O10: =SUMIF(MUTASI!$B$6:$B$45,"Pajak Restoran",MUTASI!$R$6:$R$45) -> 78088481 | P10: =IFERROR(O10/O11,"") -> 0.098162039
B11: PENDAPATAN BERSIH | C11: =IF(C$5>BLN,"",N(C9)-N(C10)) -> 90280982 | D11: =IF(D$5>BLN,"",N(D9)-N(D10)) -> 68311343 | E11: =IF(E$5>BLN,"",N(E9)-N(E10)) -> 93204021 | F11: =IF(F$5>BLN,"",N(F9)-N(F10)) -> 85954724 | G11: =IF(G$5>BLN,"",N(G9)-N(G10)) -> 102494869 | H11: =IF(H$5>BLN,"",N(H9)-N(H10)) -> 95817091 | I11: =IF(I$5>BLN,"",N(I9)-N(I10)) -> 85381495 | J11: =IF(J$5>BLN,"",N(J9)-N(J10)) -> 87841757 | ... N11: =IF(N$5>BLN,"",N(N9)-N(N10)) | O11: =N(O9)-N(O10) -> 795505902 | P11: =IFERROR(O11/O11,"") -> 1
B13: BEBAN POKOK PENJUALAN
B14: Bahan baku | C14: =IF(C$5>BLN,"",SUMIF(MUTASI!$B$6:$B$45,"Biaya Bahan Baku",MUTASI!$E$6:$E$45)) -> 25310200 | D14: =IF(D$5>BLN,"",SUMIF(MUTASI!$B$6:$B$45,"Biaya Bahan Baku",MUTASI!$F$6:$F$45)) -> 26953700 | E14: =IF(E$5>BLN,"",SUMIF(MUTASI!$B$6:$B$45,"Biaya Bahan Baku",MUTASI!$G$6:$G$45)) -> 28284387 | F14: =IF(F$5>BLN,"",SUMIF(MUTASI!$B$6:$B$45,"Biaya Bahan Baku",MUTASI!$H$6:$H$45)) -> 50730535 | G14: =IF(G$5>BLN,"",SUMIF(MUTASI!$B$6:$B$45,"Biaya Bahan Baku",MUTASI!$I$6:$I$45)) -> 31404673 | H14: =IF(H$5>BLN,"",SUMIF(MUTASI!$B$6:$B$45,"Biaya Bahan Baku",MUTASI!$J$6:$J$45)) -> 38670406 | I14: =IF(I$5>BLN,"",SUMIF(MUTASI!$B$6:$B$45,"Biaya Bahan Baku",MUTASI!$K$6:$K$45)) -> 31812694 | J14: =IF(J$5>BLN,"",SUMIF(MUTASI!$B$6:$B$45,"Biaya Bahan Baku",MUTASI!$L$6:$L$45)) -> 20123020 | K14: =IF(K$5>BLN,"",SUMIF(MUTASI!$B$6:$B$45,"Biaya Bahan Baku",MUTASI!$M$6:$M$45)) -> 49298099 | L14: =IF(L$5>BLN,"",SUMIF(MUTASI!$B$6:$B$45,"Biaya Bahan Baku",MUTASI!$N$6:$N$45)) | M14: =IF(M$5>BLN,"",SUMIF(MUTASI!$B$6:$B$45,"Biaya Bahan Baku",MUTASI!$O$6:$O$45)) | N14: =IF(N$5>BLN,"",SUMIF(MUTASI!$B$6:$B$45,"Biaya Bahan Baku",MUTASI!$P$6:$P$45)) | O14: =SUMIF(MUTASI!$B$6:$B$45,"Biaya Bahan Baku",MUTASI!$R$6:$R$45) -> 302587714 | P14: =IFERROR(O14/O11,"") -> 0.38037143
B15: Penyajian & kemasan | C15: =IF(C$5>BLN,"",SUMIF(MUTASI!$B$6:$B$45,"Biaya Penyajian",MUTASI!$E$6:$E$45)) -> 2858100 | D15: =IF(D$5>BLN,"",SUMIF(MUTASI!$B$6:$B$45,"Biaya Penyajian",MUTASI!$F$6:$F$45)) -> 4280010 | E15: =IF(E$5>BLN,"",SUMIF(MUTASI!$B$6:$B$45,"Biaya Penyajian",MUTASI!$G$6:$G$45)) -> 4752800 | F15: =IF(F$5>BLN,"",SUMIF(MUTASI!$B$6:$B$45,"Biaya Penyajian",MUTASI!$H$6:$H$45)) -> 5438259 | G15: =IF(G$5>BLN,"",SUMIF(MUTASI!$B$6:$B$45,"Biaya Penyajian",MUTASI!$I$6:$I$45)) -> 3320500 | H15: =IF(H$5>BLN,"",SUMIF(MUTASI!$B$6:$B$45,"Biaya Penyajian",MUTASI!$J$6:$J$45)) -> 6466101 | I15: =IF(I$5>BLN,"",SUMIF(MUTASI!$B$6:$B$45,"Biaya Penyajian",MUTASI!$K$6:$K$45)) -> 2105350 | J15: =IF(J$5>BLN,"",SUMIF(MUTASI!$B$6:$B$45,"Biaya Penyajian",MUTASI!$L$6:$L$45)) -> 2970000 | K15: =IF(K$5>BLN,"",SUMIF(MUTASI!$B$6:$B$45,"Biaya Penyajian",MUTASI!$M$6:$M$45)) -> 3800700 | L15: =IF(L$5>BLN,"",SUMIF(MUTASI!$B$6:$B$45,"Biaya Penyajian",MUTASI!$N$6:$N$45)) | M15: =IF(M$5>BLN,"",SUMIF(MUTASI!$B$6:$B$45,"Biaya Penyajian",MUTASI!$O$6:$O$45)) | N15: =IF(N$5>BLN,"",SUMIF(MUTASI!$B$6:$B$45,"Biaya Penyajian",MUTASI!$P$6:$P$45)) | O15: =SUMIF(MUTASI!$B$6:$B$45,"Biaya Penyajian",MUTASI!$R$6:$R$45) -> 35991820 | P15: =IFERROR(O15/O11,"") -> 0.045243938
B16: Total beban pokok penjualan | C16: =IF(C$5>BLN,"",N(C14)+N(C15)) -> 28168300 | D16: =IF(D$5>BLN,"",N(D14)+N(D15)) -> 31233710 | E16: =IF(E$5>BLN,"",N(E14)+N(E15)) -> 33037187 | F16: =IF(F$5>BLN,"",N(F14)+N(F15)) -> 56168794 | G16: =IF(G$5>BLN,"",N(G14)+N(G15)) -> 34725173 | H16: =IF(H$5>BLN,"",N(H14)+N(H15)) -> 45136507 | I16: =IF(I$5>BLN,"",N(I14)+N(I15)) -> 33918044 | J16: =IF(J$5>BLN,"",N(J14)+N(J15)) -> 23093020 | ... N16: =IF(N$5>BLN,"",N(N14)+N(N15)) | O16: =N(O14)+N(O15) -> 338579534 | P16: =IFERROR(O16/O11,"") -> 0.42561536
B18: LABA KOTOR | C18: =IF(C$5>BLN,"",N(C11)-N(C16)) -> 62112682 | D18: =IF(D$5>BLN,"",N(D11)-N(D16)) -> 37077633 | E18: =IF(E$5>BLN,"",N(E11)-N(E16)) -> 60166834 | F18: =IF(F$5>BLN,"",N(F11)-N(F16)) -> 29785930 | G18: =IF(G$5>BLN,"",N(G11)-N(G16)) -> 67769696 | H18: =IF(H$5>BLN,"",N(H11)-N(H16)) -> 50680584 | I18: =IF(I$5>BLN,"",N(I11)-N(I16)) -> 51463451 | J18: =IF(J$5>BLN,"",N(J11)-N(J16)) -> 64748737 | ... N18: =IF(N$5>BLN,"",N(N11)-N(N16)) | O18: =N(O11)-N(O16) -> 456926368 | P18: =IFERROR(O18/O11,"") -> 0.57438464
B19: Margin laba kotor | C19: =IF(C$5>BLN,"",IFERROR((N(C18))/C11,"")) -> 0.68799298 | D19: =IF(D$5>BLN,"",IFERROR((N(D18))/D11,"")) -> 0.54277418 | E19: =IF(E$5>BLN,"",IFERROR((N(E18))/E11,"")) -> 0.64553904 | F19: =IF(F$5>BLN,"",IFERROR((N(F18))/F11,"")) -> 0.34653046 | G19: =IF(G$5>BLN,"",IFERROR((N(G18))/G11,"")) -> 0.66120086 | H19: =IF(H$5>BLN,"",IFERROR((N(H18))/H11,"")) -> 0.52893052 | I19: =IF(I$5>BLN,"",IFERROR((N(I18))/I11,"")) -> 0.60274713 | J19: =IF(J$5>BLN,"",IFERROR((N(J18))/J11,"")) -> 0.73710658 | ... N19: =IF(N$5>BLN,"",IFERROR((N(N18))/N11,"")) | O19: =IFERROR((N(O18))/O11,"") -> 0.57438464
B21: BEBAN USAHA
B22: Gaji karyawan | C22: =IF(C$5>BLN,"",SUMIF(MUTASI!$B$6:$B$45,"Beban Gaji",MUTASI!$E$6:$E$45)) -> 25630000 | D22: =IF(D$5>BLN,"",SUMIF(MUTASI!$B$6:$B$45,"Beban Gaji",MUTASI!$F$6:$F$45)) -> 26694500 | E22: =IF(E$5>BLN,"",SUMIF(MUTASI!$B$6:$B$45,"Beban Gaji",MUTASI!$G$6:$G$45)) -> 42902000 | F22: =IF(F$5>BLN,"",SUMIF(MUTASI!$B$6:$B$45,"Beban Gaji",MUTASI!$H$6:$H$45)) -> 27266000 | G22: =IF(G$5>BLN,"",SUMIF(MUTASI!$B$6:$B$45,"Beban Gaji",MUTASI!$I$6:$I$45)) -> 29405333 | H22: =IF(H$5>BLN,"",SUMIF(MUTASI!$B$6:$B$45,"Beban Gaji",MUTASI!$J$6:$J$45)) -> 30293333 | I22: =IF(I$5>BLN,"",SUMIF(MUTASI!$B$6:$B$45,"Beban Gaji",MUTASI!$K$6:$K$45)) -> 22761333 | J22: =IF(J$5>BLN,"",SUMIF(MUTASI!$B$6:$B$45,"Beban Gaji",MUTASI!$L$6:$L$45)) -> 24169333 | K22: =IF(K$5>BLN,"",SUMIF(MUTASI!$B$6:$B$45,"Beban Gaji",MUTASI!$M$6:$M$45)) -> 24792333 | L22: =IF(L$5>BLN,"",SUMIF(MUTASI!$B$6:$B$45,"Beban Gaji",MUTASI!$N$6:$N$45)) | M22: =IF(M$5>BLN,"",SUMIF(MUTASI!$B$6:$B$45,"Beban Gaji",MUTASI!$O$6:$O$45)) | N22: =IF(N$5>BLN,"",SUMIF(MUTASI!$B$6:$B$45,"Beban Gaji",MUTASI!$P$6:$P$45)) | O22: =SUMIF(MUTASI!$B$6:$B$45,"Beban Gaji",MUTASI!$R$6:$R$45) -> 253914165 | P22: =IFERROR(O22/O11,"") -> 0.31918577
B23: Sewa tempat | C23: =IF(C$5>BLN,"",SUMIF(MUTASI!$B$6:$B$45,"Biaya Sewa Tempat",MUTASI!$E$6:$E$45)) -> 10000000 | D23: =IF(D$5>BLN,"",SUMIF(MUTASI!$B$6:$B$45,"Biaya Sewa Tempat",MUTASI!$F$6:$F$45)) -> 10000000 | E23: =IF(E$5>BLN,"",SUMIF(MUTASI!$B$6:$B$45,"Biaya Sewa Tempat",MUTASI!$G$6:$G$45)) -> 10000000 | F23: =IF(F$5>BLN,"",SUMIF(MUTASI!$B$6:$B$45,"Biaya Sewa Tempat",MUTASI!$H$6:$H$45)) -> 10000000 | G23: =IF(G$5>BLN,"",SUMIF(MUTASI!$B$6:$B$45,"Biaya Sewa Tempat",MUTASI!$I$6:$I$45)) -> 10000000 | H23: =IF(H$5>BLN,"",SUMIF(MUTASI!$B$6:$B$45,"Biaya Sewa Tempat",MUTASI!$J$6:$J$45)) -> 0 | I23: =IF(I$5>BLN,"",SUMIF(MUTASI!$B$6:$B$45,"Biaya Sewa Tempat",MUTASI!$K$6:$K$45)) -> 10000000 | J23: =IF(J$5>BLN,"",SUMIF(MUTASI!$B$6:$B$45,"Biaya Sewa Tempat",MUTASI!$L$6:$L$45)) -> 10000000 | K23: =IF(K$5>BLN,"",SUMIF(MUTASI!$B$6:$B$45,"Biaya Sewa Tempat",MUTASI!$M$6:$M$45)) -> 10000000 | L23: =IF(L$5>BLN,"",SUMIF(MUTASI!$B$6:$B$45,"Biaya Sewa Tempat",MUTASI!$N$6:$N$45)) | M23: =IF(M$5>BLN,"",SUMIF(MUTASI!$B$6:$B$45,"Biaya Sewa Tempat",MUTASI!$O$6:$O$45)) | N23: =IF(N$5>BLN,"",SUMIF(MUTASI!$B$6:$B$45,"Biaya Sewa Tempat",MUTASI!$P$6:$P$45)) | O23: =SUMIF(MUTASI!$B$6:$B$45,"Biaya Sewa Tempat",MUTASI!$R$6:$R$45) -> 80000000 | P23: =IFERROR(O23/O11,"") -> 0.10056494
B24: Listrik, air, internet & langganan | C24: =IF(C$5>BLN,"",SUMIF(MUTASI!$B$6:$B$45,"Biaya Tagihan Bulanan",MUTASI!$E$6:$E$45)) -> 4619448 | D24: =IF(D$5>BLN,"",SUMIF(MUTASI!$B$6:$B$45,"Biaya Tagihan Bulanan",MUTASI!$F$6:$F$45)) -> 4511384 | E24: =IF(E$5>BLN,"",SUMIF(MUTASI!$B$6:$B$45,"Biaya Tagihan Bulanan",MUTASI!$G$6:$G$45)) -> 4663782 | F24: =IF(F$5>BLN,"",SUMIF(MUTASI!$B$6:$B$45,"Biaya Tagihan Bulanan",MUTASI!$H$6:$H$45)) -> 4957412 | G24: =IF(G$5>BLN,"",SUMIF(MUTASI!$B$6:$B$45,"Biaya Tagihan Bulanan",MUTASI!$I$6:$I$45)) -> 5262141 | H24: =IF(H$5>BLN,"",SUMIF(MUTASI!$B$6:$B$45,"Biaya Tagihan Bulanan",MUTASI!$J$6:$J$45)) -> 5146765 | I24: =IF(I$5>BLN,"",SUMIF(MUTASI!$B$6:$B$45,"Biaya Tagihan Bulanan",MUTASI!$K$6:$K$45)) -> 5525230 | J24: =IF(J$5>BLN,"",SUMIF(MUTASI!$B$6:$B$45,"Biaya Tagihan Bulanan",MUTASI!$L$6:$L$45)) -> 5414662 | K24: =IF(K$5>BLN,"",SUMIF(MUTASI!$B$6:$B$45,"Biaya Tagihan Bulanan",MUTASI!$M$6:$M$45)) -> 5336097 | L24: =IF(L$5>BLN,"",SUMIF(MUTASI!$B$6:$B$45,"Biaya Tagihan Bulanan",MUTASI!$N$6:$N$45)) | M24: =IF(M$5>BLN,"",SUMIF(MUTASI!$B$6:$B$45,"Biaya Tagihan Bulanan",MUTASI!$O$6:$O$45)) | N24: =IF(N$5>BLN,"",SUMIF(MUTASI!$B$6:$B$45,"Biaya Tagihan Bulanan",MUTASI!$P$6:$P$45)) | O24: =SUMIF(MUTASI!$B$6:$B$45,"Biaya Tagihan Bulanan",MUTASI!$R$6:$R$45) -> 45436921 | P24: =IFERROR(O24/O11,"") -> 0.057117013
B25: Marketing, promosi & event | C25: =IF(C$5>BLN,"",SUMIF(MUTASI!$B$6:$B$45,"Biaya Marketing & Promosi",MUTASI!$E$6:$E$45)) -> 64039154 | D25: =IF(D$5>BLN,"",SUMIF(MUTASI!$B$6:$B$45,"Biaya Marketing & Promosi",MUTASI!$F$6:$F$45)) -> 41301 | E25: =IF(E$5>BLN,"",SUMIF(MUTASI!$B$6:$B$45,"Biaya Marketing & Promosi",MUTASI!$G$6:$G$45)) -> 0 | F25: =IF(F$5>BLN,"",SUMIF(MUTASI!$B$6:$B$45,"Biaya Marketing & Promosi",MUTASI!$H$6:$H$45)) -> 2369540 | G25: =IF(G$5>BLN,"",SUMIF(MUTASI!$B$6:$B$45,"Biaya Marketing & Promosi",MUTASI!$I$6:$I$45)) -> 1047000 | H25: =IF(H$5>BLN,"",SUMIF(MUTASI!$B$6:$B$45,"Biaya Marketing & Promosi",MUTASI!$J$6:$J$45)) -> 2470003 | I25: =IF(I$5>BLN,"",SUMIF(MUTASI!$B$6:$B$45,"Biaya Marketing & Promosi",MUTASI!$K$6:$K$45)) -> 2546500 | J25: =IF(J$5>BLN,"",SUMIF(MUTASI!$B$6:$B$45,"Biaya Marketing & Promosi",MUTASI!$L$6:$L$45)) -> 1705000 | K25: =IF(K$5>BLN,"",SUMIF(MUTASI!$B$6:$B$45,"Biaya Marketing & Promosi",MUTASI!$M$6:$M$45)) -> 4974800 | L25: =IF(L$5>BLN,"",SUMIF(MUTASI!$B$6:$B$45,"Biaya Marketing & Promosi",MUTASI!$N$6:$N$45)) | M25: =IF(M$5>BLN,"",SUMIF(MUTASI!$B$6:$B$45,"Biaya Marketing & Promosi",MUTASI!$O$6:$O$45)) | N25: =IF(N$5>BLN,"",SUMIF(MUTASI!$B$6:$B$45,"Biaya Marketing & Promosi",MUTASI!$P$6:$P$45)) | O25: =SUMIF(MUTASI!$B$6:$B$45,"Biaya Marketing & Promosi",MUTASI!$R$6:$R$45) -> 79193298 | P25: =IFERROR(O25/O11,"") -> 0.099550862
B26: Perlengkapan | C26: =IF(C$5>BLN,"",SUMIF(MUTASI!$B$6:$B$45,"Beban Perlengkapan",MUTASI!$E$6:$E$45)) -> 755900 | D26: =IF(D$5>BLN,"",SUMIF(MUTASI!$B$6:$B$45,"Beban Perlengkapan",MUTASI!$F$6:$F$45)) -> 328832 | E26: =IF(E$5>BLN,"",SUMIF(MUTASI!$B$6:$B$45,"Beban Perlengkapan",MUTASI!$G$6:$G$45)) -> 1468366 | F26: =IF(F$5>BLN,"",SUMIF(MUTASI!$B$6:$B$45,"Beban Perlengkapan",MUTASI!$H$6:$H$45)) -> 2041399 | G26: =IF(G$5>BLN,"",SUMIF(MUTASI!$B$6:$B$45,"Beban Perlengkapan",MUTASI!$I$6:$I$45)) -> 369584 | H26: =IF(H$5>BLN,"",SUMIF(MUTASI!$B$6:$B$45,"Beban Perlengkapan",MUTASI!$J$6:$J$45)) -> 1179010 | I26: =IF(I$5>BLN,"",SUMIF(MUTASI!$B$6:$B$45,"Beban Perlengkapan",MUTASI!$K$6:$K$45)) -> 1465476 | J26: =IF(J$5>BLN,"",SUMIF(MUTASI!$B$6:$B$45,"Beban Perlengkapan",MUTASI!$L$6:$L$45)) -> 2645674 | K26: =IF(K$5>BLN,"",SUMIF(MUTASI!$B$6:$B$45,"Beban Perlengkapan",MUTASI!$M$6:$M$45)) -> 3178772 | L26: =IF(L$5>BLN,"",SUMIF(MUTASI!$B$6:$B$45,"Beban Perlengkapan",MUTASI!$N$6:$N$45)) | M26: =IF(M$5>BLN,"",SUMIF(MUTASI!$B$6:$B$45,"Beban Perlengkapan",MUTASI!$O$6:$O$45)) | N26: =IF(N$5>BLN,"",SUMIF(MUTASI!$B$6:$B$45,"Beban Perlengkapan",MUTASI!$P$6:$P$45)) | O26: =SUMIF(MUTASI!$B$6:$B$45,"Beban Perlengkapan",MUTASI!$R$6:$R$45) -> 13433013 | P26: =IFERROR(O26/O11,"") -> 0.016886126
B27: Operasional harian | C27: =IF(C$5>BLN,"",SUMIF(MUTASI!$B$6:$B$45,"Biaya Operasional Harian",MUTASI!$E$6:$E$45)) -> 549900 | D27: =IF(D$5>BLN,"",SUMIF(MUTASI!$B$6:$B$45,"Biaya Operasional Harian",MUTASI!$F$6:$F$45)) -> 75000 | E27: =IF(E$5>BLN,"",SUMIF(MUTASI!$B$6:$B$45,"Biaya Operasional Harian",MUTASI!$G$6:$G$45)) -> 1282180 | F27: =IF(F$5>BLN,"",SUMIF(MUTASI!$B$6:$B$45,"Biaya Operasional Harian",MUTASI!$H$6:$H$45)) -> 452500 | G27: =IF(G$5>BLN,"",SUMIF(MUTASI!$B$6:$B$45,"Biaya Operasional Harian",MUTASI!$I$6:$I$45)) -> 634500 | H27: =IF(H$5>BLN,"",SUMIF(MUTASI!$B$6:$B$45,"Biaya Operasional Harian",MUTASI!$J$6:$J$45)) -> 521500 | I27: =IF(I$5>BLN,"",SUMIF(MUTASI!$B$6:$B$45,"Biaya Operasional Harian",MUTASI!$K$6:$K$45)) -> 450000 | J27: =IF(J$5>BLN,"",SUMIF(MUTASI!$B$6:$B$45,"Biaya Operasional Harian",MUTASI!$L$6:$L$45)) -> 310000 | K27: =IF(K$5>BLN,"",SUMIF(MUTASI!$B$6:$B$45,"Biaya Operasional Harian",MUTASI!$M$6:$M$45)) -> 620500 | L27: =IF(L$5>BLN,"",SUMIF(MUTASI!$B$6:$B$45,"Biaya Operasional Harian",MUTASI!$N$6:$N$45)) | M27: =IF(M$5>BLN,"",SUMIF(MUTASI!$B$6:$B$45,"Biaya Operasional Harian",MUTASI!$O$6:$O$45)) | N27: =IF(N$5>BLN,"",SUMIF(MUTASI!$B$6:$B$45,"Biaya Operasional Harian",MUTASI!$P$6:$P$45)) | O27: =SUMIF(MUTASI!$B$6:$B$45,"Biaya Operasional Harian",MUTASI!$R$6:$R$45) -> 4896080 | P27: =IFERROR(O27/O11,"") -> 0.0061546746
B28: Pemeliharaan | C28: =IF(C$5>BLN,"",SUMIF(MUTASI!$B$6:$B$45,"Biaya Pemeliharaan",MUTASI!$E$6:$E$45)) -> 3059350 | D28: =IF(D$5>BLN,"",SUMIF(MUTASI!$B$6:$B$45,"Biaya Pemeliharaan",MUTASI!$F$6:$F$45)) -> 78500 | E28: =IF(E$5>BLN,"",SUMIF(MUTASI!$B$6:$B$45,"Biaya Pemeliharaan",MUTASI!$G$6:$G$45)) -> 446000 | F28: =IF(F$5>BLN,"",SUMIF(MUTASI!$B$6:$B$45,"Biaya Pemeliharaan",MUTASI!$H$6:$H$45)) -> 536010 | G28: =IF(G$5>BLN,"",SUMIF(MUTASI!$B$6:$B$45,"Biaya Pemeliharaan",MUTASI!$I$6:$I$45)) -> 3680848 | H28: =IF(H$5>BLN,"",SUMIF(MUTASI!$B$6:$B$45,"Biaya Pemeliharaan",MUTASI!$J$6:$J$45)) -> 4333387 | I28: =IF(I$5>BLN,"",SUMIF(MUTASI!$B$6:$B$45,"Biaya Pemeliharaan",MUTASI!$K$6:$K$45)) -> 1214000 | J28: =IF(J$5>BLN,"",SUMIF(MUTASI!$B$6:$B$45,"Biaya Pemeliharaan",MUTASI!$L$6:$L$45)) -> 0 | K28: =IF(K$5>BLN,"",SUMIF(MUTASI!$B$6:$B$45,"Biaya Pemeliharaan",MUTASI!$M$6:$M$45)) -> 210000 | L28: =IF(L$5>BLN,"",SUMIF(MUTASI!$B$6:$B$45,"Biaya Pemeliharaan",MUTASI!$N$6:$N$45)) | M28: =IF(M$5>BLN,"",SUMIF(MUTASI!$B$6:$B$45,"Biaya Pemeliharaan",MUTASI!$O$6:$O$45)) | N28: =IF(N$5>BLN,"",SUMIF(MUTASI!$B$6:$B$45,"Biaya Pemeliharaan",MUTASI!$P$6:$P$45)) | O28: =SUMIF(MUTASI!$B$6:$B$45,"Biaya Pemeliharaan",MUTASI!$R$6:$R$45) -> 13558095 | P28: =IFERROR(O28/O11,"") -> 0.017043362
B29: Compliment | C29: =IF(C$5>BLN,"",SUMIF(MUTASI!$B$6:$B$45,"Biaya Compliment",MUTASI!$E$6:$E$45)) -> 1220000 | D29: =IF(D$5>BLN,"",SUMIF(MUTASI!$B$6:$B$45,"Biaya Compliment",MUTASI!$F$6:$F$45)) -> 339300 | E29: =IF(E$5>BLN,"",SUMIF(MUTASI!$B$6:$B$45,"Biaya Compliment",MUTASI!$G$6:$G$45)) -> 282300 | F29: =IF(F$5>BLN,"",SUMIF(MUTASI!$B$6:$B$45,"Biaya Compliment",MUTASI!$H$6:$H$45)) -> 986000 | G29: =IF(G$5>BLN,"",SUMIF(MUTASI!$B$6:$B$45,"Biaya Compliment",MUTASI!$I$6:$I$45)) -> 96000 | H29: =IF(H$5>BLN,"",SUMIF(MUTASI!$B$6:$B$45,"Biaya Compliment",MUTASI!$J$6:$J$45)) -> 166300 | I29: =IF(I$5>BLN,"",SUMIF(MUTASI!$B$6:$B$45,"Biaya Compliment",MUTASI!$K$6:$K$45)) -> 432900 | J29: =IF(J$5>BLN,"",SUMIF(MUTASI!$B$6:$B$45,"Biaya Compliment",MUTASI!$L$6:$L$45)) -> 642600 | K29: =IF(K$5>BLN,"",SUMIF(MUTASI!$B$6:$B$45,"Biaya Compliment",MUTASI!$M$6:$M$45)) -> 314600 | L29: =IF(L$5>BLN,"",SUMIF(MUTASI!$B$6:$B$45,"Biaya Compliment",MUTASI!$N$6:$N$45)) | M29: =IF(M$5>BLN,"",SUMIF(MUTASI!$B$6:$B$45,"Biaya Compliment",MUTASI!$O$6:$O$45)) | N29: =IF(N$5>BLN,"",SUMIF(MUTASI!$B$6:$B$45,"Biaya Compliment",MUTASI!$P$6:$P$45)) | O29: =SUMIF(MUTASI!$B$6:$B$45,"Biaya Compliment",MUTASI!$R$6:$R$45) -> 4480000 | P29: =IFERROR(O29/O11,"") -> 0.0056316364
B30: Riset & pengembangan menu | C30: =IF(C$5>BLN,"",SUMIF(MUTASI!$B$6:$B$45,"Biaya R&D",MUTASI!$E$6:$E$45)) -> 0 | D30: =IF(D$5>BLN,"",SUMIF(MUTASI!$B$6:$B$45,"Biaya R&D",MUTASI!$F$6:$F$45)) -> 0 | E30: =IF(E$5>BLN,"",SUMIF(MUTASI!$B$6:$B$45,"Biaya R&D",MUTASI!$G$6:$G$45)) -> 0 | F30: =IF(F$5>BLN,"",SUMIF(MUTASI!$B$6:$B$45,"Biaya R&D",MUTASI!$H$6:$H$45)) -> 0 | G30: =IF(G$5>BLN,"",SUMIF(MUTASI!$B$6:$B$45,"Biaya R&D",MUTASI!$I$6:$I$45)) -> 0 | H30: =IF(H$5>BLN,"",SUMIF(MUTASI!$B$6:$B$45,"Biaya R&D",MUTASI!$J$6:$J$45)) -> 0 | I30: =IF(I$5>BLN,"",SUMIF(MUTASI!$B$6:$B$45,"Biaya R&D",MUTASI!$K$6:$K$45)) -> 0 | J30: =IF(J$5>BLN,"",SUMIF(MUTASI!$B$6:$B$45,"Biaya R&D",MUTASI!$L$6:$L$45)) -> 0 | K30: =IF(K$5>BLN,"",SUMIF(MUTASI!$B$6:$B$45,"Biaya R&D",MUTASI!$M$6:$M$45)) -> 0 | L30: =IF(L$5>BLN,"",SUMIF(MUTASI!$B$6:$B$45,"Biaya R&D",MUTASI!$N$6:$N$45)) | M30: =IF(M$5>BLN,"",SUMIF(MUTASI!$B$6:$B$45,"Biaya R&D",MUTASI!$O$6:$O$45)) | N30: =IF(N$5>BLN,"",SUMIF(MUTASI!$B$6:$B$45,"Biaya R&D",MUTASI!$P$6:$P$45)) | O30: =SUMIF(MUTASI!$B$6:$B$45,"Biaya R&D",MUTASI!$R$6:$R$45) -> 0 | P30: =IFERROR(O30/O11,"") -> 0
B31: Dana sosial & CSR | C31: =IF(C$5>BLN,"",SUMIF(MUTASI!$B$6:$B$45,"Dana Sosial & CSR",MUTASI!$E$6:$E$45)) -> 2800000 | D31: =IF(D$5>BLN,"",SUMIF(MUTASI!$B$6:$B$45,"Dana Sosial & CSR",MUTASI!$F$6:$F$45)) -> 980000 | E31: =IF(E$5>BLN,"",SUMIF(MUTASI!$B$6:$B$45,"Dana Sosial & CSR",MUTASI!$G$6:$G$45)) -> 1440000 | F31: =IF(F$5>BLN,"",SUMIF(MUTASI!$B$6:$B$45,"Dana Sosial & CSR",MUTASI!$H$6:$H$45)) -> 800000 | G31: =IF(G$5>BLN,"",SUMIF(MUTASI!$B$6:$B$45,"Dana Sosial & CSR",MUTASI!$I$6:$I$45)) -> 1030000 | H31: =IF(H$5>BLN,"",SUMIF(MUTASI!$B$6:$B$45,"Dana Sosial & CSR",MUTASI!$J$6:$J$45)) -> 850000 | I31: =IF(I$5>BLN,"",SUMIF(MUTASI!$B$6:$B$45,"Dana Sosial & CSR",MUTASI!$K$6:$K$45)) -> 1860000 | J31: =IF(J$5>BLN,"",SUMIF(MUTASI!$B$6:$B$45,"Dana Sosial & CSR",MUTASI!$L$6:$L$45)) -> 1235000 | K31: =IF(K$5>BLN,"",SUMIF(MUTASI!$B$6:$B$45,"Dana Sosial & CSR",MUTASI!$M$6:$M$45)) -> 839000 | L31: =IF(L$5>BLN,"",SUMIF(MUTASI!$B$6:$B$45,"Dana Sosial & CSR",MUTASI!$N$6:$N$45)) | M31: =IF(M$5>BLN,"",SUMIF(MUTASI!$B$6:$B$45,"Dana Sosial & CSR",MUTASI!$O$6:$O$45)) | N31: =IF(N$5>BLN,"",SUMIF(MUTASI!$B$6:$B$45,"Dana Sosial & CSR",MUTASI!$P$6:$P$45)) | O31: =SUMIF(MUTASI!$B$6:$B$45,"Dana Sosial & CSR",MUTASI!$R$6:$R$45) -> 11834000 | P31: =IFERROR(O31/O11,"") -> 0.014876068
B32: Penyusutan peralatan | C32: =IF(C$5>BLN,"",SUMIF(MUTASI!$B$6:$B$45,"Beban Penyusutan Peralatan",MUTASI!$E$6:$E$45)) -> 0 | D32: =IF(D$5>BLN,"",SUMIF(MUTASI!$B$6:$B$45,"Beban Penyusutan Peralatan",MUTASI!$F$6:$F$45)) -> 216667 | E32: =IF(E$5>BLN,"",SUMIF(MUTASI!$B$6:$B$45,"Beban Penyusutan Peralatan",MUTASI!$G$6:$G$45)) -> 216667 | F32: =IF(F$5>BLN,"",SUMIF(MUTASI!$B$6:$B$45,"Beban Penyusutan Peralatan",MUTASI!$H$6:$H$45)) -> 252964 | G32: =IF(G$5>BLN,"",SUMIF(MUTASI!$B$6:$B$45,"Beban Penyusutan Peralatan",MUTASI!$I$6:$I$45)) -> 260452 | H32: =IF(H$5>BLN,"",SUMIF(MUTASI!$B$6:$B$45,"Beban Penyusutan Peralatan",MUTASI!$J$6:$J$45)) -> 297787 | I32: =IF(I$5>BLN,"",SUMIF(MUTASI!$B$6:$B$45,"Beban Penyusutan Peralatan",MUTASI!$K$6:$K$45)) -> 399853 | J32: =IF(J$5>BLN,"",SUMIF(MUTASI!$B$6:$B$45,"Beban Penyusutan Peralatan",MUTASI!$L$6:$L$45)) -> 426400 | K32: =IF(K$5>BLN,"",SUMIF(MUTASI!$B$6:$B$45,"Beban Penyusutan Peralatan",MUTASI!$M$6:$M$45)) -> 493329 | L32: =IF(L$5>BLN,"",SUMIF(MUTASI!$B$6:$B$45,"Beban Penyusutan Peralatan",MUTASI!$N$6:$N$45)) | M32: =IF(M$5>BLN,"",SUMIF(MUTASI!$B$6:$B$45,"Beban Penyusutan Peralatan",MUTASI!$O$6:$O$45)) | N32: =IF(N$5>BLN,"",SUMIF(MUTASI!$B$6:$B$45,"Beban Penyusutan Peralatan",MUTASI!$P$6:$P$45)) | O32: =SUMIF(MUTASI!$B$6:$B$45,"Beban Penyusutan Peralatan",MUTASI!$R$6:$R$45) -> 2564119 | P32: =IFERROR(O32/O11,"") -> 0.0032232558
B33: Total beban usaha | C33: =IF(C$5>BLN,"",N(C22)+N(C23)+N(C24)+N(C25)+N(C26)+N(C27)+N(C28)+N(C29)+N(C30)+N(C31)+N(C32)) -> 112673752 | D33: =IF(D$5>BLN,"",N(D22)+N(D23)+N(D24)+N(D25)+N(D26)+N(D27)+N(D28)+N(D29)+N(D30)+N(D31)+N(D32)) -> 43265484 | E33: =IF(E$5>BLN,"",N(E22)+N(E23)+N(E24)+N(E25)+N(E26)+N(E27)+N(E28)+N(E29)+N(E30)+N(E31)+N(E32)) -> 62701295 | F33: =IF(F$5>BLN,"",N(F22)+N(F23)+N(F24)+N(F25)+N(F26)+N(F27)+N(F28)+N(F29)+N(F30)+N(F31)+N(F32)) -> 49661825 | G33: =IF(G$5>BLN,"",N(G22)+N(G23)+N(G24)+N(G25)+N(G26)+N(G27)+N(G28)+N(G29)+N(G30)+N(G31)+N(G32)) -> 51785858 | H33: =IF(H$5>BLN,"",N(H22)+N(H23)+N(H24)+N(H25)+N(H26)+N(H27)+N(H28)+N(H29)+N(H30)+N(H31)+N(H32)) -> 45258085 | I33: =IF(I$5>BLN,"",N(I22)+N(I23)+N(I24)+N(I25)+N(I26)+N(I27)+N(I28)+N(I29)+N(I30)+N(I31)+N(I32)) -> 46655292 | J33: =IF(J$5>BLN,"",N(J22)+N(J23)+N(J24)+N(J25)+N(J26)+N(J27)+N(J28)+N(J29)+N(J30)+N(J31)+N(J32)) -> 46548669 | ... N33: =IF(N$5>BLN,"",N(N22)+N(N23)+N(N24)+N(N25)+N(N26)+N(N27)+N(N28)+N(N29)+N(N30)+N(N31)+N(N32)) | O33: =N(O22)+N(O23)+N(O24)+N(O25)+N(O26)+N(O27)+N(O28)+N(O29)+N(O30)+N(O31)+N(O32) -> 509309691 | P33: =IFERROR(O33/O11,"") -> 0.64023371
B35: LABA (RUGI) USAHA | C35: =IF(C$5>BLN,"",N(C18)-N(C33)) -> -50561070 | D35: =IF(D$5>BLN,"",N(D18)-N(D33)) -> -6187851 | E35: =IF(E$5>BLN,"",N(E18)-N(E33)) -> -2534461 | F35: =IF(F$5>BLN,"",N(F18)-N(F33)) -> -19875895 | G35: =IF(G$5>BLN,"",N(G18)-N(G33)) -> 15983838 | H35: =IF(H$5>BLN,"",N(H18)-N(H33)) -> 5422499 | I35: =IF(I$5>BLN,"",N(I18)-N(I33)) -> 4808159 | J35: =IF(J$5>BLN,"",N(J18)-N(J33)) -> 18200068 | ... N35: =IF(N$5>BLN,"",N(N18)-N(N33)) | O35: =N(O18)-N(O33) -> -52383323 | P35: =IFERROR(O35/O11,"") -> -0.065849069
B36: EBITDA (laba usaha + penyusutan) | C36: =IF(C$5>BLN,"",N(C35)+N(C32)) -> -50561070 | D36: =IF(D$5>BLN,"",N(D35)+N(D32)) -> -5971184 | E36: =IF(E$5>BLN,"",N(E35)+N(E32)) -> -2317794 | F36: =IF(F$5>BLN,"",N(F35)+N(F32)) -> -19622931 | G36: =IF(G$5>BLN,"",N(G35)+N(G32)) -> 16244290 | H36: =IF(H$5>BLN,"",N(H35)+N(H32)) -> 5720286 | I36: =IF(I$5>BLN,"",N(I35)+N(I32)) -> 5208012 | J36: =IF(J$5>BLN,"",N(J35)+N(J32)) -> 18626468 | ... N36: =IF(N$5>BLN,"",N(N35)+N(N32)) | O36: =N(O35)+N(O32) -> -49819204 | P36: =IFERROR(O36/O11,"") -> -0.062625813
B38: PENDAPATAN (BEBAN) LAIN-LAIN
B39: Pendapatan lain-lain | C39: =IF(C$5>BLN,"",-SUMIF(MUTASI!$B$6:$B$45,"Pendapatan Lainnya",MUTASI!$E$6:$E$45)) -> 104748 | D39: =IF(D$5>BLN,"",-SUMIF(MUTASI!$B$6:$B$45,"Pendapatan Lainnya",MUTASI!$F$6:$F$45)) -> 165632 | E39: =IF(E$5>BLN,"",-SUMIF(MUTASI!$B$6:$B$45,"Pendapatan Lainnya",MUTASI!$G$6:$G$45)) -> 219302 | F39: =IF(F$5>BLN,"",-SUMIF(MUTASI!$B$6:$B$45,"Pendapatan Lainnya",MUTASI!$H$6:$H$45)) -> 447496 | G39: =IF(G$5>BLN,"",-SUMIF(MUTASI!$B$6:$B$45,"Pendapatan Lainnya",MUTASI!$I$6:$I$45)) -> 133847 | H39: =IF(H$5>BLN,"",-SUMIF(MUTASI!$B$6:$B$45,"Pendapatan Lainnya",MUTASI!$J$6:$J$45)) -> 1016 | I39: =IF(I$5>BLN,"",-SUMIF(MUTASI!$B$6:$B$45,"Pendapatan Lainnya",MUTASI!$K$6:$K$45)) -> 26330 | J39: =IF(J$5>BLN,"",-SUMIF(MUTASI!$B$6:$B$45,"Pendapatan Lainnya",MUTASI!$L$6:$L$45)) -> 104920 | K39: =IF(K$5>BLN,"",-SUMIF(MUTASI!$B$6:$B$45,"Pendapatan Lainnya",MUTASI!$M$6:$M$45)) -> 13449 | L39: =IF(L$5>BLN,"",-SUMIF(MUTASI!$B$6:$B$45,"Pendapatan Lainnya",MUTASI!$N$6:$N$45)) | M39: =IF(M$5>BLN,"",-SUMIF(MUTASI!$B$6:$B$45,"Pendapatan Lainnya",MUTASI!$O$6:$O$45)) | N39: =IF(N$5>BLN,"",-SUMIF(MUTASI!$B$6:$B$45,"Pendapatan Lainnya",MUTASI!$P$6:$P$45)) | O39: =-SUMIF(MUTASI!$B$6:$B$45,"Pendapatan Lainnya",MUTASI!$R$6:$R$45) -> 1216740 | P39: =IFERROR(O39/O11,"") -> 0.0015295173
B40: Beban lain-lain (admin bank, denda) | C40: =IF(C$5>BLN,"",SUMIF(MUTASI!$B$6:$B$45,"Biaya Lainnya",MUTASI!$E$6:$E$45)) -> 691719 | D40: =IF(D$5>BLN,"",SUMIF(MUTASI!$B$6:$B$45,"Biaya Lainnya",MUTASI!$F$6:$F$45)) -> 189899 | E40: =IF(E$5>BLN,"",SUMIF(MUTASI!$B$6:$B$45,"Biaya Lainnya",MUTASI!$G$6:$G$45)) -> 1088138 | F40: =IF(F$5>BLN,"",SUMIF(MUTASI!$B$6:$B$45,"Biaya Lainnya",MUTASI!$H$6:$H$45)) -> 979111 | G40: =IF(G$5>BLN,"",SUMIF(MUTASI!$B$6:$B$45,"Biaya Lainnya",MUTASI!$I$6:$I$45)) -> 37309 | H40: =IF(H$5>BLN,"",SUMIF(MUTASI!$B$6:$B$45,"Biaya Lainnya",MUTASI!$J$6:$J$45)) -> 41481 | I40: =IF(I$5>BLN,"",SUMIF(MUTASI!$B$6:$B$45,"Biaya Lainnya",MUTASI!$K$6:$K$45)) -> 38480 | J40: =IF(J$5>BLN,"",SUMIF(MUTASI!$B$6:$B$45,"Biaya Lainnya",MUTASI!$L$6:$L$45)) -> 579041 | K40: =IF(K$5>BLN,"",SUMIF(MUTASI!$B$6:$B$45,"Biaya Lainnya",MUTASI!$M$6:$M$45)) -> 184941 | L40: =IF(L$5>BLN,"",SUMIF(MUTASI!$B$6:$B$45,"Biaya Lainnya",MUTASI!$N$6:$N$45)) | M40: =IF(M$5>BLN,"",SUMIF(MUTASI!$B$6:$B$45,"Biaya Lainnya",MUTASI!$O$6:$O$45)) | N40: =IF(N$5>BLN,"",SUMIF(MUTASI!$B$6:$B$45,"Biaya Lainnya",MUTASI!$P$6:$P$45)) | O40: =SUMIF(MUTASI!$B$6:$B$45,"Biaya Lainnya",MUTASI!$R$6:$R$45) -> 3830119 | P40: =IFERROR(O40/O11,"") -> 0.0048146959
B41: Total lain-lain bersih | C41: =IF(C$5>BLN,"",N(C39)-N(C40)) -> -586971 | D41: =IF(D$5>BLN,"",N(D39)-N(D40)) -> -24267 | E41: =IF(E$5>BLN,"",N(E39)-N(E40)) -> -868836 | F41: =IF(F$5>BLN,"",N(F39)-N(F40)) -> -531615 | G41: =IF(G$5>BLN,"",N(G39)-N(G40)) -> 96538 | H41: =IF(H$5>BLN,"",N(H39)-N(H40)) -> -40465 | I41: =IF(I$5>BLN,"",N(I39)-N(I40)) -> -12150 | J41: =IF(J$5>BLN,"",N(J39)-N(J40)) -> -474121 | ... N41: =IF(N$5>BLN,"",N(N39)-N(N40)) | O41: =N(O39)-N(O40) -> -2613379 | P41: =IFERROR(O41/O11,"") -> -0.0032851786
B43: LABA (RUGI) BERSIH | C43: =IF(C$5>BLN,"",N(C35)+N(C41)) -> -51148041 | D43: =IF(D$5>BLN,"",N(D35)+N(D41)) -> -6212118 | E43: =IF(E$5>BLN,"",N(E35)+N(E41)) -> -3403297 | F43: =IF(F$5>BLN,"",N(F35)+N(F41)) -> -20407510 | G43: =IF(G$5>BLN,"",N(G35)+N(G41)) -> 16080376 | H43: =IF(H$5>BLN,"",N(H35)+N(H41)) -> 5382034 | I43: =IF(I$5>BLN,"",N(I35)+N(I41)) -> 4796009 | J43: =IF(J$5>BLN,"",N(J35)+N(J41)) -> 17725947 | ... N43: =IF(N$5>BLN,"",N(N35)+N(N41)) | O43: =N(O35)+N(O41) -> -54996702 | P43: =IFERROR(O43/O11,"") -> -0.069134248
B44: Margin laba bersih | C44: =IF(C$5>BLN,"",IFERROR((N(C43))/C11,"")) -> -0.56654281 | D44: =IF(D$5>BLN,"",IFERROR((N(D43))/D11,"")) -> -0.090938309 | E44: =IF(E$5>BLN,"",IFERROR((N(E43))/E11,"")) -> -0.036514487 | F44: =IF(F$5>BLN,"",IFERROR((N(F43))/F11,"")) -> -0.23742162 | G44: =IF(G$5>BLN,"",IFERROR((N(G43))/G11,"")) -> 0.15688957 | H44: =IF(H$5>BLN,"",IFERROR((N(H43))/H11,"")) -> 0.056169875 | I44: =IF(I$5>BLN,"",IFERROR((N(I43))/I11,"")) -> 0.056171528 | J44: =IF(J$5>BLN,"",IFERROR((N(J43))/J11,"")) -> 0.20179409 | ... N44: =IF(N$5>BLN,"",IFERROR((N(N43))/N11,"")) | O44: =IFERROR((N(O43))/O11,"") -> -0.069134248
B46: INDIKATOR BIAYA (terhadap pendapatan bersih)
B47: Food cost (HPP) | C47: =IF(C$5>BLN,"",IFERROR((N(C16))/C11,"")) -> 0.31200702 | D47: =IF(D$5>BLN,"",IFERROR((N(D16))/D11,"")) -> 0.45722582 | E47: =IF(E$5>BLN,"",IFERROR((N(E16))/E11,"")) -> 0.35446096 | F47: =IF(F$5>BLN,"",IFERROR((N(F16))/F11,"")) -> 0.65346954 | G47: =IF(G$5>BLN,"",IFERROR((N(G16))/G11,"")) -> 0.33879914 | H47: =IF(H$5>BLN,"",IFERROR((N(H16))/H11,"")) -> 0.47106948 | I47: =IF(I$5>BLN,"",IFERROR((N(I16))/I11,"")) -> 0.39725287 | J47: =IF(J$5>BLN,"",IFERROR((N(J16))/J11,"")) -> 0.26289342 | ... N47: =IF(N$5>BLN,"",IFERROR((N(N16))/N11,"")) | O47: =IFERROR((N(O16))/O11,"") -> 0.42561536
B48: Payroll (gaji) | C48: =IF(C$5>BLN,"",IFERROR((N(C22))/C11,"")) -> 0.28389146 | D48: =IF(D$5>BLN,"",IFERROR((N(D22))/D11,"")) -> 0.39077698 | E48: =IF(E$5>BLN,"",IFERROR((N(E22))/E11,"")) -> 0.46030203 | F48: =IF(F$5>BLN,"",IFERROR((N(F22))/F11,"")) -> 0.31721351 | G48: =IF(G$5>BLN,"",IFERROR((N(G22))/G11,"")) -> 0.28689566 | H48: =IF(H$5>BLN,"",IFERROR((N(H22))/H11,"")) -> 0.31615793 | I48: =IF(I$5>BLN,"",IFERROR((N(I22))/I11,"")) -> 0.26658391 | J48: =IF(J$5>BLN,"",IFERROR((N(J22))/J11,"")) -> 0.27514628 | ... N48: =IF(N$5>BLN,"",IFERROR((N(N22))/N11,"")) | O48: =IFERROR((N(O22))/O11,"") -> 0.31918577
...

Sheet NERACA
A1: LAPORAN POSISI KEUANGAN (NERACA)
A2: ="KOPI PARANG • dalam Rupiah" -> KOPI PARANG • dalam Rupiah
B4: Keterangan | C4: ="1 Jan "&TAHUN -> 1 Jan 2026 | D4: =TEXT(DATE(TAHUN,BLN+1,0),"d")&" "&LEFT(NAMA_BLN,3)&" "&TAHUN -> 30 Sep 2026
B5: ASET
B6: Aset lancar
B7: Kas tunai | C7: =SUMIF(MUTASI!$B$6:$B$45,"Kas Tunai",MUTASI!$Q$6:$Q$45) -> 26605500 | D7: =SUMIF(MUTASI!$B$6:$B$45,"Kas Tunai",MUTASI!$S$6:$S$45) -> 51913400
B8: Kas di bank | C8: =SUMIF(MUTASI!$B$6:$B$45,"Kas Bank",MUTASI!$Q$6:$Q$45) -> 81982785 | D8: =SUMIF(MUTASI!$B$6:$B$45,"Kas Bank",MUTASI!$S$6:$S$45) -> -2739792
B9: Kas kecil (warung) | C9: =SUMIF(MUTASI!$B$6:$B$45,"Kas Warung",MUTASI!$Q$6:$Q$45) -> 3000000 | D9: =SUMIF(MUTASI!$B$6:$B$45,"Kas Warung",MUTASI!$S$6:$S$45) -> 4108000
B10: Piutang usaha | C10: =SUMIF(MUTASI!$B$6:$B$45,"Piutang Usaha Cafe",MUTASI!$Q$6:$Q$45)+SUMIF(MUTASI!$B$6:$B$45,"Piutang Usaha non Cafe",MUTASI!$Q$6:$Q$45) -> 4500000 | D10: =SUMIF(MUTASI!$B$6:$B$45,"Piutang Usaha Cafe",MUTASI!$S$6:$S$45)+SUMIF(MUTASI!$B$6:$B$45,"Piutang Usaha non Cafe",MUTASI!$S$6:$S$45) -> 0
B11: Piutang lain-lain | C11: =SUMIF(MUTASI!$B$6:$B$45,"Piutang Lainnya",MUTASI!$Q$6:$Q$45) -> 3000000 | D11: =SUMIF(MUTASI!$B$6:$B$45,"Piutang Lainnya",MUTASI!$S$6:$S$45) -> 8133335
B12: Persediaan bahan baku | C12: =SUMIF(MUTASI!$B$6:$B$45,"Inventori",MUTASI!$Q$6:$Q$45) -> 0 | D12: =SUMIF(MUTASI!$B$6:$B$45,"Inventori",MUTASI!$S$6:$S$45) -> 0
B13: Perlengkapan | C13: =SUMIF(MUTASI!$B$6:$B$45,"Perlengkapan",MUTASI!$Q$6:$Q$45) -> 0 | D13: =SUMIF(MUTASI!$B$6:$B$45,"Perlengkapan",MUTASI!$S$6:$S$45) -> 864780
B14: Beban dibayar di muka | C14: =SUMIF(MUTASI!$B$6:$B$45,"Beban Dibayar di Muka",MUTASI!$Q$6:$Q$45) -> 0 | D14: =SUMIF(MUTASI!$B$6:$B$45,"Beban Dibayar di Muka",MUTASI!$S$6:$S$45) -> 0
B15: Total aset lancar | C15: =C7+C8+C9+C10+C11+C12+C13+C14 -> 119088285 | D15: =D7+D8+D9+D10+D11+D12+D13+D14 -> 62279723
B16: Aset tidak lancar
B17: Peralatan (harga perolehan) | C17: =SUMIF(MUTASI!$B$6:$B$45,"Peralatan",MUTASI!$Q$6:$Q$45) -> 0 | D17: =SUMIF(MUTASI!$B$6:$B$45,"Peralatan",MUTASI!$S$6:$S$45) -> 42023410
B18: Akumulasi penyusutan | C18: =SUMIF(MUTASI!$B$6:$B$45,"Akumulasi Penyusutan Peralatan",MUTASI!$Q$6:$Q$45) -> 0 | D18: =SUMIF(MUTASI!$B$6:$B$45,"Akumulasi Penyusutan Peralatan",MUTASI!$S$6:$S$45) -> -2564119
B19: Total aset tidak lancar | C19: =C17+C18 -> 0 | D19: =D17+D18 -> 39459291
B20: TOTAL ASET | C20: =C15+C19 -> 119088285 | D20: =D15+D19 -> 101739014
B22: LIABILITAS DAN EKUITAS
B23: Liabilitas jangka pendek
B24: Utang usaha | C24: =-SUMIF(MUTASI!$B$6:$B$45,"Utang Usaha Lancar",MUTASI!$Q$6:$Q$45) -> 0 | D24: =-SUMIF(MUTASI!$B$6:$B$45,"Utang Usaha Lancar",MUTASI!$S$6:$S$45) -> 0
B25: Utang pajak daerah (PBJT) | C25: =-SUMIF(MUTASI!$B$6:$B$45,"Utang Pajak Daerah (PBJT)",MUTASI!$Q$6:$Q$45) -> 0 | D25: =-SUMIF(MUTASI!$B$6:$B$45,"Utang Pajak Daerah (PBJT)",MUTASI!$S$6:$S$45) -> 59326181
B26: Utang lain-lain | C26: =-SUMIF(MUTASI!$B$6:$B$45,"Utang Lainnya",MUTASI!$Q$6:$Q$45) -> 3567600 | D26: =-SUMIF(MUTASI!$B$6:$B$45,"Utang Lainnya",MUTASI!$S$6:$S$45) -> 3567600
B27: Total liabilitas jangka pendek | C27: =C24+C25+C26 -> 3567600 | D27: =D24+D25+D26 -> 62893781
B28: Liabilitas jangka panjang
B29: Utang usaha jangka panjang | C29: =-SUMIF(MUTASI!$B$6:$B$45,"Utang Usaha Jangka Panjang",MUTASI!$Q$6:$Q$45) -> 2420000 | D29: =-SUMIF(MUTASI!$B$6:$B$45,"Utang Usaha Jangka Panjang",MUTASI!$S$6:$S$45) -> 11726000
B30: TOTAL LIABILITAS | C30: =C27+C29 -> 5987600 | D30: =D27+D29 -> 74619781
B31: Ekuitas
B32: Modal pemilik | C32: =-SUMIF(MUTASI!$B$6:$B$45,"Ekuitas Kopi Parang",MUTASI!$Q$6:$Q$45) -> 113100685 | D32: =-SUMIF(MUTASI!$B$6:$B$45,"Ekuitas Kopi Parang",MUTASI!$S$6:$S$45) -> 113100685
B33: Prive (pengambilan pemilik) | C33: =-SUMIF(MUTASI!$B$6:$B$45,"Prive",MUTASI!$Q$6:$Q$45) -> 0 | D33: =-SUMIF(MUTASI!$B$6:$B$45,"Prive",MUTASI!$S$6:$S$45) -> -30984750
B34: Laba (rugi) tahun berjalan | C34: =0 -> 0 | D34: =-(SUMIF(MUTASI!$C$6:$C$45,"PENDAPATAN",MUTASI!$R$6:$R$45)+SUMIF(MUTASI!$C$6:$C$45,"BEBAN",MUTASI!$R$6:$R$45)) -> -54996702
B35: TOTAL EKUITAS | C35: =C32+C33+C34 -> 113100685 | D35: =D32+D33+D34 -> 27119233
B36: TOTAL LIABILITAS DAN EKUITAS | C36: =C30+C35 -> 119088285 | D36: =D30+D35 -> 101739014
B38: Cek keseimbangan (harus 0) | C38: =ROUND(C20-C36,0) -> 0 | D38: =ROUND(D20-D36,0) -> 0
B40: Lihat CALK untuk penjelasan pos-pos penting (saldo awal aset tetap, kewajiban pajak).

Sheet ARUS KAS
A1: LAPORAN ARUS KAS (METODE LANGSUNG)
A2: ="KOPI PARANG • "&"Periode 1 Januari – "&TEXT(DATE(TAHUN,BLN+1,0),"d")&" "&NAMA_BLN&" "&TAHUN&" • pindah dana antar-kas tidak dihitung" -> KOPI PARANG • Periode 1 Januari – 30 September 2026 • pindah dana antar-kas tidak dihitung
B4: Keterangan | C4: Jan | D4: Feb | E4: Mar | F4: Apr | G4: Mei | H4: Jun | I4: Jul | J4: Agu | K4: Sep | L4: Okt | M4: Nov | N4: Des | O4: ="s.d. "&LEFT(NAMA_BLN,3)&" "&TAHUN -> s.d. Sep 2026
C5: 1 | D5: 2 | E5: 3 | F5: 4 | G5: 5 | H5: 6 | I5: 7 | J5: 8 | K5: 9 | L5: 10 | M5: 11 | N5: 12
B6: ARUS KAS DARI AKTIVITAS OPERASI
B7: Penerimaan dari pelanggan | C7: =IF(C$5>BLN,"",SUMIFS(J_KAS,J_BARIS,"OP1",J_BLN,C$5,J_THN,TAHUN)) -> 97109977 | D7: =IF(D$5>BLN,"",SUMIFS(J_KAS,J_BARIS,"OP1",J_BLN,D$5,J_THN,TAHUN)) -> 74780788 | E7: =IF(E$5>BLN,"",SUMIFS(J_KAS,J_BARIS,"OP1",J_BLN,E$5,J_THN,TAHUN)) -> 101366744 | F7: =IF(F$5>BLN,"",SUMIFS(J_KAS,J_BARIS,"OP1",J_BLN,F$5,J_THN,TAHUN)) -> 93542488 | G7: =IF(G$5>BLN,"",SUMIFS(J_KAS,J_BARIS,"OP1",J_BLN,G$5,J_THN,TAHUN)) -> 110628974 | H7: =IF(H$5>BLN,"",SUMIFS(J_KAS,J_BARIS,"OP1",J_BLN,H$5,J_THN,TAHUN)) -> 103966227 | I7: =IF(I$5>BLN,"",SUMIFS(J_KAS,J_BARIS,"OP1",J_BLN,I$5,J_THN,TAHUN)) -> 91223181 | J7: =IF(J$5>BLN,"",SUMIFS(J_KAS,J_BARIS,"OP1",J_BLN,J$5,J_THN,TAHUN)) -> 93754284 | ... N7: =IF(N$5>BLN,"",SUMIFS(J_KAS,J_BARIS,"OP1",J_BLN,N$5,J_THN,TAHUN)) | O7: =SUMIFS(J_KAS,J_BARIS,"OP1",J_THN,TAHUN,J_BLN,"<="&BLN) -> 858725533
B8: Penerimaan (pembayaran) lain-lain bersih | C8: =IF(C$5>BLN,"",SUMIFS(J_KAS,J_BARIS,"OP2",J_BLN,C$5,J_THN,TAHUN)) -> -4274771 | D8: =IF(D$5>BLN,"",SUMIFS(J_KAS,J_BARIS,"OP2",J_BLN,D$5,J_THN,TAHUN)) -> 246033 | E8: =IF(E$5>BLN,"",SUMIFS(J_KAS,J_BARIS,"OP2",J_BLN,E$5,J_THN,TAHUN)) -> -595336 | F8: =IF(F$5>BLN,"",SUMIFS(J_KAS,J_BARIS,"OP2",J_BLN,F$5,J_THN,TAHUN)) -> -1399315 | G8: =IF(G$5>BLN,"",SUMIFS(J_KAS,J_BARIS,"OP2",J_BLN,G$5,J_THN,TAHUN)) -> -1021829 | H8: =IF(H$5>BLN,"",SUMIFS(J_KAS,J_BARIS,"OP2",J_BLN,H$5,J_THN,TAHUN)) -> 647768 | I8: =IF(I$5>BLN,"",SUMIFS(J_KAS,J_BARIS,"OP2",J_BLN,I$5,J_THN,TAHUN)) -> -595017 | J8: =IF(J$5>BLN,"",SUMIFS(J_KAS,J_BARIS,"OP2",J_BLN,J$5,J_THN,TAHUN)) -> -1288 | ... N8: =IF(N$5>BLN,"",SUMIFS(J_KAS,J_BARIS,"OP2",J_BLN,N$5,J_THN,TAHUN)) | O8: =SUMIFS(J_KAS,J_BARIS,"OP2",J_THN,TAHUN,J_BLN,"<="&BLN) -> -4842614
B9: Pembayaran bahan baku & penyajian | C9: =IF(C$5>BLN,"",SUMIFS(J_KAS,J_BARIS,"OP3",J_BLN,C$5,J_THN,TAHUN)) -> -28168300 | D9: =IF(D$5>BLN,"",SUMIFS(J_KAS,J_BARIS,"OP3",J_BLN,D$5,J_THN,TAHUN)) -> -31233710 | E9: =IF(E$5>BLN,"",SUMIFS(J_KAS,J_BARIS,"OP3",J_BLN,E$5,J_THN,TAHUN)) -> -33037187 | F9: =IF(F$5>BLN,"",SUMIFS(J_KAS,J_BARIS,"OP3",J_BLN,F$5,J_THN,TAHUN)) -> -56168794 | G9: =IF(G$5>BLN,"",SUMIFS(J_KAS,J_BARIS,"OP3",J_BLN,G$5,J_THN,TAHUN)) -> -34725173 | H9: =IF(H$5>BLN,"",SUMIFS(J_KAS,J_BARIS,"OP3",J_BLN,H$5,J_THN,TAHUN)) -> -45136507 | I9: =IF(I$5>BLN,"",SUMIFS(J_KAS,J_BARIS,"OP3",J_BLN,I$5,J_THN,TAHUN)) -> -33918044 | J9: =IF(J$5>BLN,"",SUMIFS(J_KAS,J_BARIS,"OP3",J_BLN,J$5,J_THN,TAHUN)) -> -23093020 | ... N9: =IF(N$5>BLN,"",SUMIFS(J_KAS,J_BARIS,"OP3",J_BLN,N$5,J_THN,TAHUN)) | O9: =SUMIFS(J_KAS,J_BARIS,"OP3",J_THN,TAHUN,J_BLN,"<="&BLN) -> -338579534
B10: Pembayaran gaji | C10: =IF(C$5>BLN,"",SUMIFS(J_KAS,J_BARIS,"OP4",J_BLN,C$5,J_THN,TAHUN)) -> -24630000 | D10: =IF(D$5>BLN,"",SUMIFS(J_KAS,J_BARIS,"OP4",J_BLN,D$5,J_THN,TAHUN)) -> -25694500 | E10: =IF(E$5>BLN,"",SUMIFS(J_KAS,J_BARIS,"OP4",J_BLN,E$5,J_THN,TAHUN)) -> -41902000 | F10: =IF(F$5>BLN,"",SUMIFS(J_KAS,J_BARIS,"OP4",J_BLN,F$5,J_THN,TAHUN)) -> -26266000 | G10: =IF(G$5>BLN,"",SUMIFS(J_KAS,J_BARIS,"OP4",J_BLN,G$5,J_THN,TAHUN)) -> -28405333 | H10: =IF(H$5>BLN,"",SUMIFS(J_KAS,J_BARIS,"OP4",J_BLN,H$5,J_THN,TAHUN)) -> -29293333 | I10: =IF(I$5>BLN,"",SUMIFS(J_KAS,J_BARIS,"OP4",J_BLN,I$5,J_THN,TAHUN)) -> -22761333 | J10: =IF(J$5>BLN,"",SUMIFS(J_KAS,J_BARIS,"OP4",J_BLN,J$5,J_THN,TAHUN)) -> -24169333 | ... N10: =IF(N$5>BLN,"",SUMIFS(J_KAS,J_BARIS,"OP4",J_BLN,N$5,J_THN,TAHUN)) | O10: =SUMIFS(J_KAS,J_BARIS,"OP4",J_THN,TAHUN,J_BLN,"<="&BLN) -> -247914165
B11: Pembayaran sewa | C11: =IF(C$5>BLN,"",SUMIFS(J_KAS,J_BARIS,"OP5",J_BLN,C$5,J_THN,TAHUN)) -> -10000000 | D11: =IF(D$5>BLN,"",SUMIFS(J_KAS,J_BARIS,"OP5",J_BLN,D$5,J_THN,TAHUN)) -> -10000000 | E11: =IF(E$5>BLN,"",SUMIFS(J_KAS,J_BARIS,"OP5",J_BLN,E$5,J_THN,TAHUN)) -> -10000000 | F11: =IF(F$5>BLN,"",SUMIFS(J_KAS,J_BARIS,"OP5",J_BLN,F$5,J_THN,TAHUN)) -> -10000000 | G11: =IF(G$5>BLN,"",SUMIFS(J_KAS,J_BARIS,"OP5",J_BLN,G$5,J_THN,TAHUN)) -> -10000000 | H11: =IF(H$5>BLN,"",SUMIFS(J_KAS,J_BARIS,"OP5",J_BLN,H$5,J_THN,TAHUN)) -> 0 | I11: =IF(I$5>BLN,"",SUMIFS(J_KAS,J_BARIS,"OP5",J_BLN,I$5,J_THN,TAHUN)) -> -10000000 | J11: =IF(J$5>BLN,"",SUMIFS(J_KAS,J_BARIS,"OP5",J_BLN,J$5,J_THN,TAHUN)) -> -10000000 | ... N11: =IF(N$5>BLN,"",SUMIFS(J_KAS,J_BARIS,"OP5",J_BLN,N$5,J_THN,TAHUN)) | O11: =SUMIFS(J_KAS,J_BARIS,"OP5",J_THN,TAHUN,J_BLN,"<="&BLN) -> -80000000
B12: Pembayaran beban operasional lainnya | C12: =IF(C$5>BLN,"",SUMIFS(J_KAS,J_BARIS,"OP6",J_BLN,C$5,J_THN,TAHUN)) -> -71813952 | D12: =IF(D$5>BLN,"",SUMIFS(J_KAS,J_BARIS,"OP6",J_BLN,D$5,J_THN,TAHUN)) -> -8624317 | E12: =IF(E$5>BLN,"",SUMIFS(J_KAS,J_BARIS,"OP6",J_BLN,E$5,J_THN,TAHUN)) -> -9300328 | F12: =IF(F$5>BLN,"",SUMIFS(J_KAS,J_BARIS,"OP6",J_BLN,F$5,J_THN,TAHUN)) -> -11156861 | G12: =IF(G$5>BLN,"",SUMIFS(J_KAS,J_BARIS,"OP6",J_BLN,G$5,J_THN,TAHUN)) -> -12024073 | H12: =IF(H$5>BLN,"",SUMIFS(J_KAS,J_BARIS,"OP6",J_BLN,H$5,J_THN,TAHUN)) -> -14500665 | I12: =IF(I$5>BLN,"",SUMIFS(J_KAS,J_BARIS,"OP6",J_BLN,I$5,J_THN,TAHUN)) -> -19061206 | J12: =IF(J$5>BLN,"",SUMIFS(J_KAS,J_BARIS,"OP6",J_BLN,J$5,J_THN,TAHUN)) -> -11310336 | ... N12: =IF(N$5>BLN,"",SUMIFS(J_KAS,J_BARIS,"OP6",J_BLN,N$5,J_THN,TAHUN)) | O12: =SUMIFS(J_KAS,J_BARIS,"OP6",J_THN,TAHUN,J_BLN,"<="&BLN) -> -173815687
B13: Pembayaran pajak restoran (PBJT) | C13: =IF(C$5>BLN,"",SUMIFS(J_KAS,J_BARIS,"OP7",J_BLN,C$5,J_THN,TAHUN)) -> -2056200 | D13: =IF(D$5>BLN,"",SUMIFS(J_KAS,J_BARIS,"OP7",J_BLN,D$5,J_THN,TAHUN)) -> -1664000 | E13: =IF(E$5>BLN,"",SUMIFS(J_KAS,J_BARIS,"OP7",J_BLN,E$5,J_THN,TAHUN)) -> -2310000 | F13: =IF(F$5>BLN,"",SUMIFS(J_KAS,J_BARIS,"OP7",J_BLN,F$5,J_THN,TAHUN)) -> -2058000 | G13: =IF(G$5>BLN,"",SUMIFS(J_KAS,J_BARIS,"OP7",J_BLN,G$5,J_THN,TAHUN)) -> -2257000 | H13: =IF(H$5>BLN,"",SUMIFS(J_KAS,J_BARIS,"OP7",J_BLN,H$5,J_THN,TAHUN)) -> -2232000 | I13: =IF(I$5>BLN,"",SUMIFS(J_KAS,J_BARIS,"OP7",J_BLN,I$5,J_THN,TAHUN)) -> -2094000 | J13: =IF(J$5>BLN,"",SUMIFS(J_KAS,J_BARIS,"OP7",J_BLN,J$5,J_THN,TAHUN)) -> -1995100 | ... N13: =IF(N$5>BLN,"",SUMIFS(J_KAS,J_BARIS,"OP7",J_BLN,N$5,J_THN,TAHUN)) | O13: =SUMIFS(J_KAS,J_BARIS,"OP7",J_THN,TAHUN,J_BLN,"<="&BLN) -> -18762300
B14: Kas bersih dari aktivitas operasi | C14: =IF(C$5>BLN,"",N(C7)+N(C8)+N(C9)+N(C10)+N(C11)+N(C12)+N(C13)) -> -43833246 | D14: =IF(D$5>BLN,"",N(D7)+N(D8)+N(D9)+N(D10)+N(D11)+N(D12)+N(D13)) -> -2189706 | E14: =IF(E$5>BLN,"",N(E7)+N(E8)+N(E9)+N(E10)+N(E11)+N(E12)+N(E13)) -> 4221893 | F14: =IF(F$5>BLN,"",N(F7)+N(F8)+N(F9)+N(F10)+N(F11)+N(F12)+N(F13)) -> -13506482 | G14: =IF(G$5>BLN,"",N(G7)+N(G8)+N(G9)+N(G10)+N(G11)+N(G12)+N(G13)) -> 22195566 | H14: =IF(H$5>BLN,"",N(H7)+N(H8)+N(H9)+N(H10)+N(H11)+N(H12)+N(H13)) -> 13451490 | I14: =IF(I$5>BLN,"",N(I7)+N(I8)+N(I9)+N(I10)+N(I11)+N(I12)+N(I13)) -> 2793581 | J14: =IF(J$5>BLN,"",N(J7)+N(J8)+N(J9)+N(J10)+N(J11)+N(J12)+N(J13)) -> 23185207 | ... N14: =IF(N$5>BLN,"",N(N7)+N(N8)+N(N9)+N(N10)+N(N11)+N(N12)+N(N13)) | O14: =N(O7)+N(O8)+N(O9)+N(O10)+N(O11)+N(O12)+N(O13) -> -5188767
B16: ARUS KAS DARI AKTIVITAS INVESTASI
B17: Pembelian peralatan | C17: =IF(C$5>BLN,"",SUMIFS(J_KAS,J_BARIS,"IN1",J_BLN,C$5,J_THN,TAHUN)) -> -13000000 | D17: =IF(D$5>BLN,"",SUMIFS(J_KAS,J_BARIS,"IN1",J_BLN,D$5,J_THN,TAHUN)) -> 0 | E17: =IF(E$5>BLN,"",SUMIFS(J_KAS,J_BARIS,"IN1",J_BLN,E$5,J_THN,TAHUN)) -> -1742240 | F17: =IF(F$5>BLN,"",SUMIFS(J_KAS,J_BARIS,"IN1",J_BLN,F$5,J_THN,TAHUN)) -> -359448 | G17: =IF(G$5>BLN,"",SUMIFS(J_KAS,J_BARIS,"IN1",J_BLN,G$5,J_THN,TAHUN)) -> -1792100 | H17: =IF(H$5>BLN,"",SUMIFS(J_KAS,J_BARIS,"IN1",J_BLN,H$5,J_THN,TAHUN)) -> -5650980 | I17: =IF(I$5>BLN,"",SUMIFS(J_KAS,J_BARIS,"IN1",J_BLN,I$5,J_THN,TAHUN)) -> -1274220 | J17: =IF(J$5>BLN,"",SUMIFS(J_KAS,J_BARIS,"IN1",J_BLN,J$5,J_THN,TAHUN)) -> -3212587 | ... N17: =IF(N$5>BLN,"",SUMIFS(J_KAS,J_BARIS,"IN1",J_BLN,N$5,J_THN,TAHUN)) | O17: =SUMIFS(J_KAS,J_BARIS,"IN1",J_THN,TAHUN,J_BLN,"<="&BLN) -> -29231410
B18: Kas bersih dari aktivitas investasi | C18: =IF(C$5>BLN,"",N(C17)) -> -13000000 | D18: =IF(D$5>BLN,"",N(D17)) -> 0 | E18: =IF(E$5>BLN,"",N(E17)) -> -1742240 | F18: =IF(F$5>BLN,"",N(F17)) -> -359448 | G18: =IF(G$5>BLN,"",N(G17)) -> -1792100 | H18: =IF(H$5>BLN,"",N(H17)) -> -5650980 | I18: =IF(I$5>BLN,"",N(I17)) -> -1274220 | J18: =IF(J$5>BLN,"",N(J17)) -> -3212587 | ... N18: =IF(N$5>BLN,"",N(N17)) | O18: =N(O17) -> -29231410
B20: ARUS KAS DARI AKTIVITAS PENDANAAN
B21: Pengambilan pemilik (prive) | C21: =IF(C$5>BLN,"",SUMIFS(J_KAS,J_BARIS,"FN1",J_BLN,C$5,J_THN,TAHUN)) -> -2500000 | D21: =IF(D$5>BLN,"",SUMIFS(J_KAS,J_BARIS,"FN1",J_BLN,D$5,J_THN,TAHUN)) -> -2500000 | E21: =IF(E$5>BLN,"",SUMIFS(J_KAS,J_BARIS,"FN1",J_BLN,E$5,J_THN,TAHUN)) -> -2500000 | F21: =IF(F$5>BLN,"",SUMIFS(J_KAS,J_BARIS,"FN1",J_BLN,F$5,J_THN,TAHUN)) -> -2500000 | G21: =IF(G$5>BLN,"",SUMIFS(J_KAS,J_BARIS,"FN1",J_BLN,G$5,J_THN,TAHUN)) -> -2500000 | H21: =IF(H$5>BLN,"",SUMIFS(J_KAS,J_BARIS,"FN1",J_BLN,H$5,J_THN,TAHUN)) -> -2500000 | I21: =IF(I$5>BLN,"",SUMIFS(J_KAS,J_BARIS,"FN1",J_BLN,I$5,J_THN,TAHUN)) -> -4000000 | J21: =IF(J$5>BLN,"",SUMIFS(J_KAS,J_BARIS,"FN1",J_BLN,J$5,J_THN,TAHUN)) -> 0 | ... N21: =IF(N$5>BLN,"",SUMIFS(J_KAS,J_BARIS,"FN1",J_BLN,N$5,J_THN,TAHUN)) | O21: =SUMIFS(J_KAS,J_BARIS,"FN1",J_THN,TAHUN,J_BLN,"<="&BLN) -> -19000000
B22: Setoran modal pemilik | C22: =IF(C$5>BLN,"",SUMIFS(J_KAS,J_BARIS,"FN2",J_BLN,C$5,J_THN,TAHUN)) -> 0 | D22: =IF(D$5>BLN,"",SUMIFS(J_KAS,J_BARIS,"FN2",J_BLN,D$5,J_THN,TAHUN)) -> 0 | E22: =IF(E$5>BLN,"",SUMIFS(J_KAS,J_BARIS,"FN2",J_BLN,E$5,J_THN,TAHUN)) -> 0 | F22: =IF(F$5>BLN,"",SUMIFS(J_KAS,J_BARIS,"FN2",J_BLN,F$5,J_THN,TAHUN)) -> 0 | G22: =IF(G$5>BLN,"",SUMIFS(J_KAS,J_BARIS,"FN2",J_BLN,G$5,J_THN,TAHUN)) -> 0 | H22: =IF(H$5>BLN,"",SUMIFS(J_KAS,J_BARIS,"FN2",J_BLN,H$5,J_THN,TAHUN)) -> 0 | I22: =IF(I$5>BLN,"",SUMIFS(J_KAS,J_BARIS,"FN2",J_BLN,I$5,J_THN,TAHUN)) -> 0 | J22: =IF(J$5>BLN,"",SUMIFS(J_KAS,J_BARIS,"FN2",J_BLN,J$5,J_THN,TAHUN)) -> 0 | ... N22: =IF(N$5>BLN,"",SUMIFS(J_KAS,J_BARIS,"FN2",J_BLN,N$5,J_THN,TAHUN)) | O22: =SUMIFS(J_KAS,J_BARIS,"FN2",J_THN,TAHUN,J_BLN,"<="&BLN) -> 0
B23: Penerimaan (pembayaran) utang | C23: =IF(C$5>BLN,"",SUMIFS(J_KAS,J_BARIS,"FN3",J_BLN,C$5,J_THN,TAHUN)) -> -1920000 | D23: =IF(D$5>BLN,"",SUMIFS(J_KAS,J_BARIS,"FN3",J_BLN,D$5,J_THN,TAHUN)) -> -522000 | E23: =IF(E$5>BLN,"",SUMIFS(J_KAS,J_BARIS,"FN3",J_BLN,E$5,J_THN,TAHUN)) -> -1378500 | F23: =IF(F$5>BLN,"",SUMIFS(J_KAS,J_BARIS,"FN3",J_BLN,F$5,J_THN,TAHUN)) -> 0 | G23: =IF(G$5>BLN,"",SUMIFS(J_KAS,J_BARIS,"FN3",J_BLN,G$5,J_THN,TAHUN)) -> 0 | H23: =IF(H$5>BLN,"",SUMIFS(J_KAS,J_BARIS,"FN3",J_BLN,H$5,J_THN,TAHUN)) -> 0 | I23: =IF(I$5>BLN,"",SUMIFS(J_KAS,J_BARIS,"FN3",J_BLN,I$5,J_THN,TAHUN)) -> 0 | J23: =IF(J$5>BLN,"",SUMIFS(J_KAS,J_BARIS,"FN3",J_BLN,J$5,J_THN,TAHUN)) -> 0 | ... N23: =IF(N$5>BLN,"",SUMIFS(J_KAS,J_BARIS,"FN3",J_BLN,N$5,J_THN,TAHUN)) | O23: =SUMIFS(J_KAS,J_BARIS,"FN3",J_THN,TAHUN,J_BLN,"<="&BLN) -> -4886500
B24: Kas bersih dari aktivitas pendanaan | C24: =IF(C$5>BLN,"",N(C21)+N(C22)+N(C23)) -> -4420000 | D24: =IF(D$5>BLN,"",N(D21)+N(D22)+N(D23)) -> -3022000 | E24: =IF(E$5>BLN,"",N(E21)+N(E22)+N(E23)) -> -3878500 | F24: =IF(F$5>BLN,"",N(F21)+N(F22)+N(F23)) -> -2500000 | G24: =IF(G$5>BLN,"",N(G21)+N(G22)+N(G23)) -> -2500000 | H24: =IF(H$5>BLN,"",N(H21)+N(H22)+N(H23)) -> -2500000 | I24: =IF(I$5>BLN,"",N(I21)+N(I22)+N(I23)) -> -4000000 | J24: =IF(J$5>BLN,"",N(J21)+N(J22)+N(J23)) -> 0 | ... N24: =IF(N$5>BLN,"",N(N21)+N(N22)+N(N23)) | O24: =N(O21)+N(O22)+N(O23) -> -23886500
B26: KENAIKAN (PENURUNAN) KAS BERSIH | C26: =IF(C$5>BLN,"",N(C14)+N(C18)+N(C24)) -> -61253246 | D26: =IF(D$5>BLN,"",N(D14)+N(D18)+N(D24)) -> -5211706 | E26: =IF(E$5>BLN,"",N(E14)+N(E18)+N(E24)) -> -1398847 | F26: =IF(F$5>BLN,"",N(F14)+N(F18)+N(F24)) -> -16365930 | G26: =IF(G$5>BLN,"",N(G14)+N(G18)+N(G24)) -> 17903466 | H26: =IF(H$5>BLN,"",N(H14)+N(H18)+N(H24)) -> 5300510 | I26: =IF(I$5>BLN,"",N(I14)+N(I18)+N(I24)) -> -2480639 | J26: =IF(J$5>BLN,"",N(J14)+N(J18)+N(J24)) -> 19972620 | ... N26: =IF(N$5>BLN,"",N(N14)+N(N18)+N(N24)) | O26: =N(O14)+N(O18)+N(O24) -> -58306677
B27: Kas awal periode | C27: =IF(C$5>BLN,"",SUMIF(MUTASI!$T$6:$T$45,"KAS",MUTASI!$Q$6:$Q$45)) -> 111588285 | D27: =IF(D$5>BLN,"",N(C28)) -> 50335039 | E27: =IF(E$5>BLN,"",N(D28)) -> 45123333 | F27: =IF(F$5>BLN,"",N(E28)) -> 43724486 | G27: =IF(G$5>BLN,"",N(F28)) -> 27358556 | H27: =IF(H$5>BLN,"",N(G28)) -> 45262022 | I27: =IF(I$5>BLN,"",N(H28)) -> 50562532 | J27: =IF(J$5>BLN,"",N(I28)) -> 48081893 | K27: =IF(K$5>BLN,"",N(J28)) -> 68054513 | ... N27: =IF(N$5>BLN,"",N(M28)) | O27: =SUMIF(MUTASI!$T$6:$T$45,"KAS",MUTASI!$Q$6:$Q$45) -> 111588285
